Workbook

Sheet Edad2
A1: cod_edad | B1: 2017 | C1: Hombres_2017 | D1: Mujeres_2017 | E1: 2018 | F1: Hombres_2018 | G1: Mujeres_2018 | H1: 2019 | I1: Hombres_2019 | J1: Mujeres_2019 | K1: 2020 | L1: Hombres_2020 | M1: Mujeres_2020 | N1: 2021 | O1: Hombres_2021 | P1: Mujeres_2021 | Q1: 2022 | R1: Hombres_2022 | S1: Mujeres_2022 | T1: 2023 | U1: Hombres_2023 | V1: Mujeres_2023
A2: 86 | B2: 1421 | C2: 701 | D2: 720 | E2: 1366 | F2: 656 | G2: 710 | H2: 1518 | I2: 778 | J2: 740 | K2: 1890 | L2: 982 | M2: 908 | N2: 1618 | O2: 781 | P2: 837 | Q2: 1703 | R2: 826 | S2: 877 | T2: 1634 | U2: 798 | V2: 836
A3: 87 | B3: 1410 | C3: 678 | D3: 732 | E3: 1443 | F3: 691 | G3: 752 | H3: 1417 | I3: 674 | J3: 743 | K3: 1846 | L3: 929 | M3: 917 | N3: 1580 | O3: 799 | P3: 781 | Q3: 1624 | R3: 763 | S3: 861 | T3: 1596 | U3: 744 | V3: 852
A4: 85 | B4: 1386 | C4: 697 | D4: 689 | E4: 1347 | F4: 679 | G4: 668 | H4: 1494 | I4: 751 | J4: 743 | K4: 1827 | L4: 986 | M4: 841 | N4: 1714 | O4: 891 | P4: 823 | Q4: 1658 | R4: 829 | S4: 829 | T4: 1552 | U4: 766 | V4: 786
A5: 84 | B5: 1359 | C5: 673 | D5: 686 | E5: 1426 | F5: 714 | G5: 712 | H5: 1401 | I5: 712 | J5: 689 | K5: 1866 | L5: 977 | M5: 889 | N5: 1619 | O5: 851 | P5: 768 | Q5: 1633 | R5: 829 | S5: 804 | T5: 1564 | U5: 802 | V5: 762
A6: 83 | B6: 1336 | C6: 688 | D6: 648 | E6: 1293 | F6: 650 | G6: 643 | H6: 1513 | I6: 793 | J6: 720 | K6: 1803 | L6: 1022 | M6: 781 | N6: 1588 | O6: 819 | P6: 769 | Q6: 1536 | R6: 728 | S6: 808 | T6: 1601 | U6: 805 | V6: 796
A7: 88 | B7: 1312 | C7: 623 | D7: 689 | E7: 1397 | F7: 668 | G7: 729 | H7: 1387 | I7: 674 | J7: 713 | K7: 1798 | L7: 893 | M7: 905 | N7: 1566 | O7: 728 | P7: 838 | Q7: 1640 | R7: 779 | S7: 861 | T7: 1513 | U7: 721 | V7: 792
A8: 81 | B8: 1300 | C8: 633 | D8: 667 | E8: 1294 | F8: 671 | G8: 623 | H8: 1344 | I8: 685 | J8: 659 | K8: 1878 | L8: 1030 | M8: 848 | N8: 1627 | O8: 876 | P8: 751 | Q8: 1540 | R8: 830 | S8: 710 | T8: 1416 | U8: 721 | V8: 695
A9: 82 | B9: 1300 | C9: 685 | D9: 615 | E9: 1341 | F9: 699 | G9: 642 | H9: 1375 | I9: 720 | J9: 655 | K9: 1784 | L9: 948 | M9: 836 | N9: 1600 | O9: 862 | P9: 738 | Q9: 1670 | R9: 878 | S9: 792 | T9: 1572 | U9: 820 | V9: 752
A10: 79 | B10: 1231 | C10: 651 | D10: 580 | E10: 1216 | F10: 638 | G10: 578 | H10: 1275 | I10: 675 | J10: 600 | K10: 1723 | L10: 992 | M10: 731 | N10: 1507 | O10: 801 | P10: 706 | Q10: 1454 | R10: 769 | S10: 685 | T10: 1443 | U10: 766 | V10: 677
A11: 78 | B11: 1216 | C11: 669 | D11: 547 | E11: 1238 | F11: 696 | G11: 542 | H11: 1228 | I11: 646 | J11: 582 | K11: 1736 | L11: 964 | M11: 772 | N11: 1460 | O11: 813 | P11: 647 | Q11: 1381 | R11: 739 | S11: 642 | T11: 1504 | U11: 829 | V11: 675
A12: 77 | B12: 1214 | C12: 666 | D12: 548 | E12: 1150 | F12: 584 | G12: 566 | H12: 1141 | I12: 622 | J12: 519 | K12: 1675 | L12: 943 | M12: 732 | N12: 1455 | O12: 794 | P12: 661 | Q12: 1495 | R12: 803 | S12: 692 | T12: 1363 | U12: 721 | V12: 642
A13: 90 | B13: 1166 | C13: 553 | D13: 613 | E13: 1096 | F13: 484 | G13: 612 | H13: 1400 | I13: 626 | J13: 774 | K13: 1664 | L13: 796 | M13: 868 | N13: 1538 | O13: 673 | P13: 865 | Q13: 1483 | R13: 666 | S13: 817 | T13: 1420 | U13: 631 | V13: 789
... A109: 107 | B109: 15 | C109: 6 | D109: 9 | E109: 18 | F109: 8 | G109: 10 | H109: 19 | I109: 7 | J109: 12 | K109: 15 | L109: 4 | M109: 11 | N109: 18 | O109: 3 | P109: 15 | Q109: 13 | R109: 4 | S109: 9 | T109: 10 | U109: 2 | V109: 8
A110: 110 | B110: 5 | C110: 1 | D110: 4 | E110: 1 | G110: 1 | H110: 1 | I110: 1 | K110: 7 | L110: 3 | M110: 4 | N110: 5 | O110: 2 | P110: 3 | Q110: 4 | R110: 1 | S110: 3 | T110: 4 | V110: 4
A111: 108 | B111: 4 | C111: 3 | D111: 1 | E111: 7 | F111: 5 | G111: 2 | H111: 12 | I111: 3 | J111: 9 | K111: 5 | L111: 2 | M111: 3 | N111: 6 | P111: 6 | Q111: 7 | R111: 3 | S111: 4 | T111: 8 | U111: 2 | V111: 6
A112: 111 | B112: 2 | C112: 1 | D112: 1 | E112: 3 | F112: 2 | G112: 1 | H112: 2 | J112: 2 | K112: 3 | M112: 3 | Q112: 1 | S112: 1 | T112: 2 | V112: 2
A113: 116 | B113: 2 | C113: 1 | D113: 1 | K113: 1 | L113: 1
A114: 117 | B114: 2 | C114: 1 | D114: 1 | K114: 1 | L114: 1
A115: 113 | B115: 1 | C115: 1 | E115: 1 | G115: 1 | H115: 3 | I115: 1 | J115: 2 | K115: 2 | L115: 1 | M115: 1 | Q115: 2 | R115: 1 | S115: 1 | T115: 1 | V115: 1
A116: 114 | B116: 1 | D116: 1 | K116: 3 | L116: 3
A117: 999 | B117: 1 | C117: 1 | E117: 4 | F117: 4 | H117: 28 | I117: 15 | J117: 13 | Q117: 2 | S117: 2 | T117: 2 | U117: 2
A118: 109 | E118: 7 | F118: 2 | G118: 5 | H118: 2 | I118: 2 | K118: 6 | L118: 3 | M118: 3 | N118: 4 | O118: 1 | P118: 3 | Q118: 7 | R118: 2 | S118: 5 | T118: 7 | U118: 1 | V118: 6
A119: 118 | E119: 2 | G119: 2 | H119: 1 | I119: 1
A120: 112 | H120: 1 | J120: 1 | K120: 1 | M120: 1 | N120: 1 | P120: 1 | Q120: 1 | R120: 1 | T120: 2 | V120: 2
A121: 115 | H121: 1 | J121: 1 | Q121: 1 | R121: 1
A122: 119 | H122: 1 | I122: 1 | K122: 2 | L122: 2
A123: 120 | N123: 2 | O123: 2 | T123: 1 | V123: 1

Sheet TDEDAD
A1: cod_edad | B1: 2017 | C1: 2018 | D1: 2019 | E1: 2020 | F1: 2021 | G1: 2022 | H1: 2023 | I1: Hombres_2017 | J1: Hombres_2018 | K1: Hombres_2019 | L1: Hombres_2020 | M1: Hombres_2021 | N1: Hombres_2022 | O1: Hombres_2023 | P1: Mujeres_2017 | Q1: Mujeres_2018 | R1: Mujeres_2019 | S1: Mujeres_2020 | T1: Mujeres_2021 | U1: Mujeres_2022 | V1: Mujeres_2023 | W1: VAR_AÑO1 | X1: VAR_AÑO2 | Y1: VAR_AÑO3 | Z1: VAR_AÑO4 | AA1: VAR_AÑO5 | AB1: VAR_AÑO6 | AC1: PROMEDIO | AD1: MEDIA | AE1: VARAB_AÑO1 | AF1: VARAB_AÑO2 | AG1: VARAB_AÑO3 | AH1: VARAB_AÑO4 | AI1: VARAB_AÑO5 | AJ1: VARAB_AÑO6 | AK1: PROMEDIO2 | AL1: MEDIA2 | AM1: VARH_AÑO1 | AN1: VARH_AÑO2 | AO1: VARH_AÑO3 | AP1: VARH_AÑO4 | AQ1: VARH_AÑO5 | AR1: VARH_AÑO6 | AS1: PROMEDIO3 | AT1: MEDIA3 | AU1: VARAH_AÑO1 | AV1: VARAH_AÑO2 | AW1: VARAH_AÑO3 | AX1: VARAH_AÑO4 | AY1: VARAH_AÑO5 | AZ1: VARAH_AÑO6 | BA1: PROMEDIO4 | BB1: MEDIA4 | BC1: VARM_AÑO1 | BD1: VARM_AÑO2 | BE1: VARM_AÑO3 | BF1: VARM_AÑO4 | BG1: VARM_AÑO5 | BH1: VARM_AÑO6 | BI1: PROMEDIO5 | BJ1: MEDIANA | BK1: VARAM_AÑO1 | BL1: VARAM_AÑO2 | BM1: VARAM_AÑO3 | BN1: VARAM_AÑO4 | BO1: VARAM_AÑO5 | BP1: VARAM_AÑO6 | BQ1: PROMEDIO6 | BR1: MEDIA5
A2: 0 | B2: 31 | C2: 55 | D2: 58 | E2: 43 | F2: 46 | G2: 36 | H2: 34 | I2: 14 | J2: 34 | K2: 30 | L2: 21 | M2: 24 | N2: 23 | O2: 24 | P2: 17 | Q2: 21 | R2: 28 | S2: 22 | T2: 22 | U2: 13 | V2: 10 | W2: =+(C2-B2)/B2 -> 0.77419355 | X2: =+(D2-C2)/C2 -> 0.054545455 | Y2: =+(E2-D2)/D2 -> -0.25862069 | Z2: =+(F2-E2)/E2 -> 0.069767442 | AA2: =+(G2-F2)/F2 -> -0.2173913 | AB2: =+(H2-G2)/G2 -> -0.055555556 | AC2: =+AVERAGE(W2:AB2) -> 0.061156483 | AD2: =MEDIAN(W2:AB2) -> -0.00050505051 | AE2: =C2-B2 -> 24 | AF2: =D2-C2 -> 3 | AG2: =E2-D2 -> -15 | AH2: =F2-E2 -> 3 | AI2: =G2-F2 -> -10 | AJ2: =H2-G2 -> -2 | AK2: =+AVERAGE(AE2:AJ2) -> 0.5 | AL2: =+MEDIAN(AE2:AJ2) -> 0.5 | AM2: =+(J2-I2)/I2 -> 1.4285714 | AN2: =+(K2-J2)/J2 -> -0.11764706 | AO2: =+(L2-K2)/K2 -> -0.3 | AP2: =+(M2-L2)/L2 -> 0.14285714 | AQ2: =+(N2-M2)/M2 -> -0.041666667 | AR2: =+(O2-N2)/N2 -> 0.043478261 | AS2: =+AVERAGE(AM2:AR2) -> 0.19259885 | AT2: =+MEDIAN(AM2:AR2) -> 0.0009057971 | AU2: =J2-I2 -> 20 | AV2: =K2-J2 -> -4 | AW2: =L2-K2 -> -9 | AX2: =M2-L2 -> 3 | AY2: =N2-M2 -> -1 | AZ2: =O2-N2 -> 1 | BA2: =+AVERAGE(AU2:AZ2) -> 1.6666667 | BB2: =MEDIAN(AU2:AZ2) -> 0 | BC2: =+(Q2-P2)/P2 -> 0.23529412 | BD2: =+(R2-Q2)/Q2 -> 0.33333333 | BE2: =+(S2-R2)/R2 -> -0.21428571 | BF2: =+(T2-S2)/S2 -> 0 | BG2: =+(U2-T2)/T2 -> -0.40909091 | BH2: =+(V2-U2)/U2 -> -0.23076923 | BI2: =+AVERAGE(BC2:BH2) -> -0.047586401 | BJ2: =MEDIAN(BC2:BH2) -> -0.10714286 | BK2: =+Q2-P2 -> 4 | BL2: =+R2-Q2 -> 7 | BM2: =+S2-R2 -> -6 | BN2: =+T2-S2 -> 0 | BO2: =+U2-T2 -> -9 | BP2: =+V2-U2 -> -3 | BQ2: =+AVERAGE(BK2:BP2) -> -1.1666667 | BR2: =MEDIAN(BK2:BP2) -> -1.5
A3: 1 | B3: 490 | C3: 464 | D3: 419 | E3: 292 | F3: 328 | G3: 338 | H3: 370 | I3: 267 | J3: 249 | K3: 228 | L3: 161 | M3: 194 | N3: 184 | O3: 207 | P3: 223 | Q3: 215 | R3: 191 | S3: 131 | T3: 134 | U3: 154 | V3: 163 | W3: =+(C3-B3)/B3 -> -0.053061224 | X3: =+(D3-C3)/C3 -> -0.096982759 | Y3: =+(E3-D3)/D3 -> -0.30310263 | Z3: =+(F3-E3)/E3 -> 0.12328767 | AA3: =+(G3-F3)/F3 -> 0.030487805 | AB3: =+(H3-G3)/G3 -> 0.094674556 | AC3: =+AVERAGE(W3:AB3) -> -0.034116096 | AD3: =MEDIAN(W3:AB3) -> -0.01128671 | AE3: =C3-B3 -> -26 | AF3: =D3-C3 -> -45 | AG3: =E3-D3 -> -127 | AH3: =F3-E3 -> 36 | AI3: =G3-F3 -> 10 | AJ3: =H3-G3 -> 32 | AK3: =+AVERAGE(AE3:AJ3) -> -20 | AL3: =+MEDIAN(AE3:AJ3) -> -8 | AM3: =+(J3-I3)/I3 -> -0.06741573 | AN3: =+(K3-J3)/J3 -> -0.084337349 | AO3: =+(L3-K3)/K3 -> -0.29385965 | AP3: =+(M3-L3)/L3 -> 0.20496894 | AQ3: =+(N3-M3)/M3 -> -0.051546392 | AR3: =+(O3-N3)/N3 -> 0.125 | AS3: =+AVERAGE(AM3:AR3) -> -0.027865029 | AT3: =+MEDIAN(AM3:AR3) -> -0.059481061 | AU3: =J3-I3 -> -18 | AV3: =K3-J3 -> -21 | AW3: =L3-K3 -> -67 | AX3: =M3-L3 -> 33 | AY3: =N3-M3 -> -10 | AZ3: =O3-N3 -> 23 | BA3: =+AVERAGE(AU3:AZ3) -> -10 | BB3: =MEDIAN(AU3:AZ3) -> -14 | BC3: =+(Q3-P3)/P3 -> -0.035874439 | BD3: =+(R3-Q3)/Q3 -> -0.11162791 | BE3: =+(S3-R3)/R3 -> -0.31413613 | BF3: =+(T3-S3)/S3 -> 0.022900763 | BG3: =+(U3-T3)/T3 -> 0.14925373 | BH3: =+(V3-U3)/U3 -> 0.058441558 | BI3: =+AVERAGE(BC3:BH3) -> -0.03850707 | BJ3: =MEDIAN(BC3:BH3) -> -0.0064868381 | BK3: =+Q3-P3 -> -8 | BL3: =+R3-Q3 -> -24 | BM3: =+S3-R3 -> -60 | BN3: =+T3-S3 -> 3 | BO3: =+U3-T3 -> 20 | BP3: =+V3-U3 -> 9 | BQ3: =+AVERAGE(BK3:BP3) -> -10 | BR3: =MEDIAN(BK3:BP3) -> -2.5
A4: 2 | B4: 265 | C4: 297 | D4: 297 | E4: 203 | F4: 195 | G4: 243 | H4: 238 | I4: 146 | J4: 156 | K4: 156 | L4: 102 | M4: 114 | N4: 118 | O4: 125 | P4: 119 | Q4: 141 | R4: 141 | S4: 101 | T4: 81 | U4: 125 | V4: 113 | W4: =+(C4-B4)/B4 -> 0.12075472 | X4: =+(D4-C4)/C4 -> 0 | Y4: =+(E4-D4)/D4 -> -0.31649832 | Z4: =+(F4-E4)/E4 -> -0.039408867 | AA4: =+(G4-F4)/F4 -> 0.24615385 | AB4: =+(H4-G4)/G4 -> -0.020576132 | AC4: =+AVERAGE(W4:AB4) -> -0.001595792 | AD4: =MEDIAN(W4:AB4) -> -0.010288066 | AE4: =C4-B4 -> 32 | AF4: =D4-C4 -> 0 | AG4: =E4-D4 -> -94 | AH4: =F4-E4 -> -8 | AI4: =G4-F4 -> 48 | AJ4: =H4-G4 -> -5 | AK4: =+AVERAGE(AE4:AJ4) -> -4.5 | AL4: =+MEDIAN(AE4:AJ4) -> -2.5 | AM4: =+(J4-I4)/I4 -> 0.068493151 | AN4: =+(K4-J4)/J4 -> 0 | AO4: =+(L4-K4)/K4 -> -0.34615385 | AP4: =+(M4-L4)/L4 -> 0.11764706 | AQ4: =+(N4-M4)/M4 -> 0.035087719 | AR4: =+(O4-N4)/N4 -> 0.059322034 | AS4: =+AVERAGE(AM4:AR4) -> -0.010933981 | AT4: =+MEDIAN(AM4:AR4) -> 0.047204877 | AU4: =J4-I4 -> 10 | AV4: =K4-J4 -> 0 | AW4: =L4-K4 -> -54 | AX4: =M4-L4 -> 12 | AY4: =N4-M4 -> 4 | AZ4: =O4-N4 -> 7 | BA4: =+AVERAGE(AU4:AZ4) -> -3.5 | BB4: =MEDIAN(AU4:AZ4) -> 5.5 | BC4: =+(Q4-P4)/P4 -> 0.18487395 | BD4: =+(R4-Q4)/Q4 -> 0 | BE4: =+(S4-R4)/R4 -> -0.28368794 | BF4: =+(T4-S4)/S4 -> -0.1980198 | BG4: =+(U4-T4)/T4 -> 0.54320988 | BH4: =+(V4-U4)/U4 -> -0.096 | BI4: =+AVERAGE(BC4:BH4) -> 0.02506268 | BJ4: =MEDIAN(BC4:BH4) -> -0.048 | BK4: =+Q4-P4 -> 22 | BL4: =+R4-Q4 -> 0 | BM4: =+S4-R4 -> -40 | BN4: =+T4-S4 -> -20 | BO4: =+U4-T4 -> 44 | BP4: =+V4-U4 -> -12 | BQ4: =+AVERAGE(BK4:BP4) -> -1 | BR4: =MEDIAN(BK4:BP4) -> -6
A5: 3 | B5: 190 | C5: 178 | D5: 177 | E5: 126 | F5: 155 | G5: 162 | H5: 145 | I5: 106 | J5: 99 | K5: 90 | L5: 68 | M5: 79 | N5: 95 | O5: 77 | P5: 84 | Q5: 79 | R5: 87 | S5: 58 | T5: 76 | U5: 67 | V5: 68 | W5: =+(C5-B5)/B5 -> -0.063157895 | X5: =+(D5-C5)/C5 -> -0.0056179775 | Y5: =+(E5-D5)/D5 -> -0.28813559 | Z5: =+(F5-E5)/E5 -> 0.23015873 | AA5: =+(G5-F5)/F5 -> 0.04516129 | AB5: =+(H5-G5)/G5 -> -0.10493827 | AC5: =+AVERAGE(W5:AB5) -> -0.031088286 | AD5: =MEDIAN(W5:AB5) -> -0.034387936 | AE5: =C5-B5 -> -12 | AF5: =D5-C5 -> -1 | AG5: =E5-D5 -> -51 | AH5: =F5-E5 -> 29 | AI5: =G5-F5 -> 7 | AJ5: =H5-G5 -> -17 | AK5: =+AVERAGE(AE5:AJ5) -> -7.5 | AL5: =+MEDIAN(AE5:AJ5) -> -6.5 | AM5: =+(J5-I5)/I5 -> -0.066037736 | AN5: =+(K5-J5)/J5 -> -0.090909091 | AO5: =+(L5-K5)/K5 -> -0.24444444 | AP5: =+(M5-L5)/L5 -> 0.16176471 | AQ5: =+(N5-M5)/M5 -> 0.20253165 | AR5: =+(O5-N5)/N5 -> -0.18947368 | AS5: =+AVERAGE(AM5:AR5) -> -0.037761434 | AT5: =+MEDIAN(AM5:AR5) -> -0.078473413 | AU5: =J5-I5 -> -7 | AV5: =K5-J5 -> -9 | AW5: =L5-K5 -> -22 | AX5: =M5-L5 -> 11 | AY5: =N5-M5 -> 16 | AZ5: =O5-N5 -> -18 | BA5: =+AVERAGE(AU5:AZ5) -> -4.8333333 | BB5: =MEDIAN(AU5:AZ5) -> -8 | BC5: =+(Q5-P5)/P5 -> -0.05952381 | BD5: =+(R5-Q5)/Q5 -> 0.10126582 | BE5: =+(S5-R5)/R5 -> -0.33333333 | BF5: =+(T5-S5)/S5 -> 0.31034483 | BG5: =+(U5-T5)/T5 -> -0.11842105 | BH5: =+(V5-U5)/U5 -> 0.014925373 | BI5: =+AVERAGE(BC5:BH5) -> -0.014123695 | BJ5: =MEDIAN(BC5:BH5) -> -0.022299218 | BK5: =+Q5-P5 -> -5 | BL5: =+R5-Q5 -> 8 | BM5: =+S5-R5 -> -29 | BN5: =+T5-S5 -> 18 | BO5: =+U5-T5 -> -9 | BP5: =+V5-U5 -> 1 | BQ5: =+AVERAGE(BK5:BP5) -> -2.6666667 | BR5: =MEDIAN(BK5:BP5) -> -2
A6: 4 | B6: 164 | C6: 128 | D6: 139 | E6: 132 | F6: 118 | G6: 121 | H6: 126 | I6: 79 | J6: 67 | K6: 81 | L6: 76 | M6: 57 | N6: 56 | O6: 75 | P6: 85 | Q6: 61 | R6: 58 | S6: 56 | T6: 61 | U6: 65 | V6: 51 | W6: =+(C6-B6)/B6 -> -0.2195122 | X6: =+(D6-C6)/C6 -> 0.0859375 | Y6: =+(E6-D6)/D6 -> -0.050359712 | Z6: =+(F6-E6)/E6 -> -0.10606061 | AA6: =+(G6-F6)/F6 -> 0.025423729 | AB6: =+(H6-G6)/G6 -> 0.041322314 | AC6: =+AVERAGE(W6:AB6) -> -0.037208162 | AD6: =MEDIAN(W6:AB6) -> -0.012467992 | AE6: =C6-B6 -> -36 | AF6: =D6-C6 -> 11 | AG6: =E6-D6 -> -7 | AH6: =F6-E6 -> -14 | AI6: =G6-F6 -> 3 | AJ6: =H6-G6 -> 5 | AK6: =+AVERAGE(AE6:AJ6) -> -6.3333333 | AL6: =+MEDIAN(AE6:AJ6) -> -2 | AM6: =+(J6-I6)/I6 -> -0.15189873 | AN6: =+(K6-J6)/J6 -> 0.20895522 | AO6: =+(L6-K6)/K6 -> -0.061728395 | AP6: =+(M6-L6)/L6 -> -0.25 | AQ6: =+(N6-M6)/M6 -> -0.01754386 | AR6: =+(O6-N6)/N6 -> 0.33928571 | AS6: =+AVERAGE(AM6:AR6) -> 0.011178325 | AT6: =+MEDIAN(AM6:AR6) -> -0.039636127 | AU6: =J6-I6 -> -12 | AV6: =K6-J6 -> 14 | AW6: =L6-K6 -> -5 | AX6: =M6-L6 -> -19 | AY6: =N6-M6 -> -1 | AZ6: =O6-N6 -> 19 | BA6: =+AVERAGE(AU6:AZ6) -> -0.66666667 | BB6: =MEDIAN(AU6:AZ6) -> -3 | BC6: =+(Q6-P6)/P6 -> -0.28235294 | BD6: =+(R6-Q6)/Q6 -> -0.049180328 | BE6: =+(S6-R6)/R6 -> -0.034482759 | BF6: =+(T6-S6)/S6 -> 0.089285714 | BG6: =+(U6-T6)/T6 -> 0.06557377 | BH6: =+(V6-U6)/U6 -> -0.21538462 | BI6: =+AVERAGE(BC6:BH6) -> -0.071090193 | BJ6: =MEDIAN(BC6:BH6) -> -0.041831543 | BK6: =+Q6-P6 -> -24 | BL6: =+R6-Q6 -> -3 | BM6: =+S6-R6 -> -2 | BN6: =+T6-S6 -> 5 | BO6: =+U6-T6 -> 4 | BP6: =+V6-U6 -> -14 | BQ6: =+AVERAGE(BK6:BP6) -> -5.6666667 | BR6: =MEDIAN(BK6:BP6) -> -2.5
A7: 5 | B7: 126 | C7: 127 | D7: 111 | E7: 70 | F7: 83 | G7: 105 | H7: 100 | I7: 66 | J7: 61 | K7: 61 | L7: 40 | M7: 46 | N7: 46 | O7: 51 | P7: 60 | Q7: 66 | R7: 50 | S7: 30 | T7: 37 | U7: 59 | V7: 49 | W7: =+(C7-B7)/B7 -> 0.0079365079 | X7: =+(D7-C7)/C7 -> -0.12598425 | Y7: =+(E7-D7)/D7 -> -0.36936937 | Z7: =+(F7-E7)/E7 -> 0.18571429 | AA7: =+(G7-F7)/F7 -> 0.26506024 | AB7: =+(H7-G7)/G7 -> -0.047619048 | AC7: =+AVERAGE(W7:AB7) -> -0.014043606 | AD7: =MEDIAN(W7:AB7) -> -0.01984127 | AE7: =C7-B7 -> 1 | AF7: =D7-C7 -> -16 | AG7: =E7-D7 -> -41 | AH7: =F7-E7 -> 13 | AI7: =G7-F7 -> 22 | AJ7: =H7-G7 -> -5 | AK7: =+AVERAGE(AE7:AJ7) -> -4.3333333 | AL7: =+MEDIAN(AE7:AJ7) -> -2 | AM7: =+(J7-I7)/I7 -> -0.075757576 | AN7: =+(K7-J7)/J7 -> 0 | AO7: =+(L7-K7)/K7 -> -0.3442623 | AP7: =+(M7-L7)/L7 -> 0.15 | AQ7: =+(N7-M7)/M7 -> 0 | AR7: =+(O7-N7)/N7 -> 0.10869565 | AS7: =+AVERAGE(AM7:AR7) -> -0.02688737 | AT7: =+MEDIAN(AM7:AR7) -> 0 | AU7: =J7-I7 -> -5 | AV7: =K7-J7 -> 0 | AW7: =L7-K7 -> -21 | AX7: =M7-L7 -> 6 | AY7: =N7-M7 -> 0 | AZ7: =O7-N7 -> 5 | BA7: =+AVERAGE(AU7:AZ7) -> -2.5 | BB7: =MEDIAN(AU7:AZ7) -> 0 | BC7: =+(Q7-P7)/P7 -> 0.1 | BD7: =+(R7-Q7)/Q7 -> -0.24242424 | BE7: =+(S7-R7)/R7 -> -0.4 | BF7: =+(T7-S7)/S7 -> 0.23333333 | BG7: =+(U7-T7)/T7 -> 0.59459459 | BH7: =+(V7-U7)/U7 -> -0.16949153 | BI7: =+AVERAGE(BC7:BH7) -> 0.01933536 | BJ7: =MEDIAN(BC7:BH7) -> -0.034745763 | BK7: =+Q7-P7 -> 6 | BL7: =+R7-Q7 -> -16 | BM7: =+S7-R7 -> -20 | BN7: =+T7-S7 -> 7 | BO7: =+U7-T7 -> 22 | BP7: =+V7-U7 -> -10 | BQ7: =+AVERAGE(BK7:BP7) -> -1.8333333 | BR7: =MEDIAN(BK7:BP7) -> -2
A8: 6 | B8: 123 | C8: 97 | D8: 95 | E8: 90 | F8: 95 | G8: 93 | H8: 102 | I8: 75 | J8: 48 | K8: 46 | L8: 51 | M8: 49 | N8: 41 | O8: 55 | P8: 48 | Q8: 49 | R8: 49 | S8: 39 | T8: 46 | U8: 52 | V8: 47 | W8: =+(C8-B8)/B8 -> -0.21138211 | X8: =+(D8-C8)/C8 -> -0.020618557 | Y8: =+(E8-D8)/D8 -> -0.052631579 | Z8: =+(F8-E8)/E8 -> 0.055555556 | AA8: =+(G8-F8)/F8 -> -0.021052632 | AB8: =+(H8-G8)/G8 -> 0.096774194 | AC8: =+AVERAGE(W8:AB8) -> -0.025559189 | AD8: =MEDIAN(W8:AB8) -> -0.020835594 | AE8: =C8-B8 -> -26 | AF8: =D8-C8 -> -2 | AG8: =E8-D8 -> -5 | AH8: =F8-E8 -> 5 | AI8: =G8-F8 -> -2 | AJ8: =H8-G8 -> 9 | AK8: =+AVERAGE(AE8:AJ8) -> -3.5 | AL8: =+MEDIAN(AE8:AJ8) -> -2 | AM8: =+(J8-I8)/I8 -> -0.36 | AN8: =+(K8-J8)/J8 -> -0.041666667 | AO8: =+(L8-K8)/K8 -> 0.10869565 | AP8: =+(M8-L8)/L8 -> -0.039215686 | AQ8: =+(N8-M8)/M8 -> -0.16326531 | AR8: =+(O8-N8)/N8 -> 0.34146341 | AS8: =+AVERAGE(AM8:AR8) -> -0.025664765 | AT8: =+MEDIAN(AM8:AR8) -> -0.040441176 | AU8: =J8-I8 -> -27 | AV8: =K8-J8 -> -2 | AW8: =L8-K8 -> 5 | AX8: =M8-L8 -> -2 | AY8: =N8-M8 -> -8 | AZ8: =O8-N8 -> 14 | BA8: =+AVERAGE(AU8:AZ8) -> -3.3333333 | BB8: =MEDIAN(AU8:AZ8) -> -2 | BC8: =+(Q8-P8)/P8 -> 0.020833333 | BD8: =+(R8-Q8)/Q8 -> 0 | BE8: =+(S8-R8)/R8 -> -0.20408163 | BF8: =+(T8-S8)/S8 -> 0.17948718 | BG8: =+(U8-T8)/T8 -> 0.13043478 | BH8: =+(V8-U8)/U8 -> -0.096153846 | BI8: =+AVERAGE(BC8:BH8) -> 0.0050866361 | BJ8: =MEDIAN(BC8:BH8) -> 0.010416667 | BK8: =+Q8-P8 -> 1 | BL8: =+R8-Q8 -> 0 | BM8: =+S8-R8 -> -10 | BN8: =+T8-S8 -> 7 | BO8: =+U8-T8 -> 6 | BP8: =+V8-U8 -> -5 | BQ8: =+AVERAGE(BK8:BP8) -> -0.16666667 | BR8: =MEDIAN(BK8:BP8) -> 0.5
A9: 7 | B9: 92 | C9: 111 | D9: 87 | E9: 63 | F9: 65 | G9: 99 | H9: 80 | I9: 50 | J9: 63 | K9: 53 | L9: 31 | M9: 37 | N9: 57 | O9: 36 | P9: 42 | Q9: 48 | R9: 34 | S9: 32 | T9: 28 | U9: 42 | V9: 44 | W9: =+(C9-B9)/B9 -> 0.20652174 | X9: =+(D9-C9)/C9 -> -0.21621622 | Y9: =+(E9-D9)/D9 -> -0.27586207 | Z9: =+(F9-E9)/E9 -> 0.031746032 | AA9: =+(G9-F9)/F9 -> 0.52307692 | AB9: =+(H9-G9)/G9 -> -0.19191919 | AC9: =+AVERAGE(W9:AB9) -> 0.012891203 | AD9: =MEDIAN(W9:AB9) -> -0.08008658 | AE9: =C9-B9 -> 19 | AF9: =D9-C9 -> -24 | AG9: =E9-D9 -> -24 | AH9: =F9-E9 -> 2 | AI9: =G9-F9 -> 34 | AJ9: =H9-G9 -> -19 | AK9: =+AVERAGE(AE9:AJ9) -> -2 | AL9: =+MEDIAN(AE9:AJ9) -> -8.5 | AM9: =+(J9-I9)/I9 -> 0.26 | AN9: =+(K9-J9)/J9 -> -0.15873016 | AO9: =+(L9-K9)/K9 -> -0.41509434 | AP9: =+(M9-L9)/L9 -> 0.19354839 | AQ9: =+(N9-M9)/M9 -> 0.54054054 | AR9: =+(O9-N9)/N9 -> -0.36842105 | AS9: =+AVERAGE(AM9:AR9) -> 0.0086405628 | AT9: =+MEDIAN(AM9:AR9) -> 0.017409114 | AU9: =J9-I9 -> 13 | AV9: =K9-J9 -> -10 | AW9: =L9-K9 -> -22 | AX9: =M9-L9 -> 6 | AY9: =N9-M9 -> 20 | AZ9: =O9-N9 -> -21 | BA9: =+AVERAGE(AU9:AZ9) -> -2.3333333 | BB9: =MEDIAN(AU9:AZ9) -> -2 | BC9: =+(Q9-P9)/P9 -> 0.14285714 | BD9: =+(R9-Q9)/Q9 -> -0.29166667 | BE9: =+(S9-R9)/R9 -> -0.058823529 | BF9: =+(T9-S9)/S9 -> -0.125 | BG9: =+(U9-T9)/T9 -> 0.5 | BH9: =+(V9-U9)/U9 -> 0.047619048 | BI9: =+AVERAGE(BC9:BH9) -> 0.035830999 | BJ9: =MEDIAN(BC9:BH9) -> -0.0056022409 | BK9: =+Q9-P9 -> 6 | BL9: =+R9-Q9 -> -14 | BM9: =+S9-R9 -> -2 | BN9: =+T9-S9 -> -4 | BO9: =+U9-T9 -> 14 | BP9: =+V9-U9 -> 2 | BQ9: =+AVERAGE(BK9:BP9) -> 0.33333333 | BR9: =MEDIAN(BK9:BP9) -> 0
A10: 8 | B10: 100 | C10: 83 | D10: 90 | E10: 66 | F10: 62 | G10: 84 | H10: 81 | I10: 54 | J10: 37 | K10: 48 | L10: 37 | M10: 31 | N10: 44 | O10: 41 | P10: 46 | Q10: 46 | R10: 42 | S10: 29 | T10: 31 | U10: 40 | V10: 40 | W10: =+(C10-B10)/B10 -> -0.17 | X10: =+(D10-C10)/C10 -> 0.084337349 | Y10: =+(E10-D10)/D10 -> -0.26666667 | Z10: =+(F10-E10)/E10 -> -0.060606061 | AA10: =+(G10-F10)/F10 -> 0.35483871 | AB10: =+(H10-G10)/G10 -> -0.035714286 | AC10: =+AVERAGE(W10:AB10) -> -0.015635159 | AD10: =MEDIAN(W10:AB10) -> -0.048160173 | AE10: =C10-B10 -> -17 | AF10: =D10-C10 -> 7 | AG10: =E10-D10 -> -24 | AH10: =F10-E10 -> -4 | AI10: =G10-F10 -> 22 | AJ10: =H10-G10 -> -3 | AK10: =+AVERAGE(AE10:AJ10) -> -3.1666667 | AL10: =+MEDIAN(AE10:AJ10) -> -3.5 | AM10: =+(J10-I10)/I10 -> -0.31481481 | AN10: =+(K10-J10)/J10 -> 0.2972973 | AO10: =+(L10-K10)/K10 -> -0.22916667 | AP10: =+(M10-L10)/L10 -> -0.16216216 | AQ10: =+(N10-M10)/M10 -> 0.41935484 | AR10: =+(O10-N10)/N10 -> -0.068181818 | AS10: =+AVERAGE(AM10:AR10) -> -0.009612221 | AT10: =+MEDIAN(AM10:AR10) -> -0.11517199 | AU10: =J10-I10 -> -17 | AV10: =K10-J10 -> 11 | AW10: =L10-K10 -> -11 | AX10: =M10-L10 -> -6 | AY10: =N10-M10 -> 13 | AZ10: =O10-N10 -> -3 | BA10: =+AVERAGE(AU10:AZ10) -> -2.1666667 | BB10: =MEDIAN(AU10:AZ10) -> -4.5 | BC10: =+(Q10-P10)/P10 -> 0 | BD10: =+(R10-Q10)/Q10 -> -0.086956522 | BE10: =+(S10-R10)/R10 -> -0.30952381 | BF10: =+(T10-S10)/S10 -> 0.068965517 | BG10: =+(U10-T10)/T10 -> 0.29032258 | BH10: =+(V10-U10)/U10 -> 0 | BI10: =+AVERAGE(BC10:BH10) -> -0.0061987056 | BJ10: =MEDIAN(BC10:BH10) -> 0 | BK10: =+Q10-P10 -> 0 | BL10: =+R10-Q10 -> -4 | BM10: =+S10-R10 -> -13 | BN10: =+T10-S10 -> 2 | BO10: =+U10-T10 -> 9 | BP10: =+V10-U10 -> 0 | BQ10: =+AVERAGE(BK10:BP10) -> -1 | BR10: =MEDIAN(BK10:BP10) -> 0
A11: 9 | B11: 84 | C11: 80 | D11: 96 | E11: 70 | F11: 86 | G11: 61 | H11: 82 | I11: 38 | J11: 39 | K11: 48 | L11: 39 | M11: 42 | N11: 33 | O11: 50 | P11: 46 | Q11: 41 | R11: 48 | S11: 31 | T11: 44 | U11: 28 | V11: 32 | W11: =+(C11-B11)/B11 -> -0.047619048 | X11: =+(D11-C11)/C11 -> 0.2 | Y11: =+(E11-D11)/D11 -> -0.27083333 | Z11: =+(F11-E11)/E11 -> 0.22857143 | AA11: =+(G11-F11)/F11 -> -0.29069767 | AB11: =+(H11-G11)/G11 -> 0.3442623 | AC11: =+AVERAGE(W11:AB11) -> 0.027280611 | AD11: =MEDIAN(W11:AB11) -> 0.076190476 | AE11: =C11-B11 -> -4 | AF11: =D11-C11 -> 16 | AG11: =E11-D11 -> -26 | AH11: =F11-E11 -> 16 | AI11: =G11-F11 -> -25 | AJ11: =H11-G11 -> 21 | AK11: =+AVERAGE(AE11:AJ11) -> -0.33333333 | AL11: =+MEDIAN(AE11:AJ11) -> 6 | AM11: =+(J11-I11)/I11 -> 0.026315789 | AN11: =+(K11-J11)/J11 -> 0.23076923 | AO11: =+(L11-K11)/K11 -> -0.1875 | AP11: =+(M11-L11)/L11 -> 0.076923077 | AQ11: =+(N11-M11)/M11 -> -0.21428571 | AR11: =+(O11-N11)/N11 -> 0.51515152 | AS11: =+AVERAGE(AM11:AR11) -> 0.074562316 | AT11: =+MEDIAN(AM11:AR11) -> 0.051619433 | AU11: =J11-I11 -> 1 | AV11: =K11-J11 -> 9 | AW11: =L11-K11 -> -9 | AX11: =M11-L11 -> 3 | AY11: =N11-M11 -> -9 | AZ11: =O11-N11 -> 17 | BA11: =+AVERAGE(AU11:AZ11) -> 2 | BB11: =MEDIAN(AU11:AZ11) -> 2 | BC11: =+(Q11-P11)/P11 -> -0.10869565 | BD11: =+(R11-Q11)/Q11 -> 0.17073171 | BE11: =+(S11-R11)/R11 -> -0.35416667 | BF11: =+(T11-S11)/S11 -> 0.41935484 | BG11: =+(U11-T11)/T11 -> -0.36363636 | BH11: =+(V11-U11)/U11 -> 0.14285714 | BI11: =+AVERAGE(BC11:BH11) -> -0.015592499 | BJ11: =MEDIAN(BC11:BH11) -> 0.017080745 | BK11: =+Q11-P11 -> -5 | BL11: =+R11-Q11 -> 7 | BM11: =+S11-R11 -> -17 | BN11: =+T11-S11 -> 13 | BO11: =+U11-T11 -> -16 | BP11: =+V11-U11 -> 4 | BQ11: =+AVERAGE(BK11:BP11) -> -2.3333333 | BR11: =MEDIAN(BK11:BP11) -> -0.5
A12: 10 | B12: 68 | C12: 73 | D12: 73 | E12: 62 | F12: 61 | G12: 71 | H12: 64 | I12: 36 | J12: 40 | K12: 31 | L12: 29 | M12: 30 | N12: 36 | O12: 36 | P12: 32 | Q12: 33 | R12: 42 | S12: 33 | T12: 31 | U12: 35 | V12: 28 | W12: =+(C12-B12)/B12 -> 0.073529412 | X12: =+(D12-C12)/C12 -> 0 | Y12: =+(E12-D12)/D12 -> -0.15068493 | Z12: =+(F12-E12)/E12 -> -0.016129032 | AA12: =+(G12-F12)/F12 -> 0.16393443 | AB12: =+(H12-G12)/G12 -> -0.098591549 | AC12: =+AVERAGE(W12:AB12) -> -0.0046569458 | AD12: =MEDIAN(W12:AB12) -> -0.0080645161 | AE12: =C12-B12 -> 5 | AF12: =D12-C12 -> 0 | AG12: =E12-D12 -> -11 | AH12: =F12-E12 -> -1 | AI12: =G12-F12 -> 10 | AJ12: =H12-G12 -> -7 | AK12: =+AVERAGE(AE12:AJ12) -> -0.66666667 | AL12: =+MEDIAN(AE12:AJ12) -> -0.5 | AM12: =+(J12-I12)/I12 -> 0.11111111 | AN12: =+(K12-J12)/J12 -> -0.225 | AO12: =+(L12-K12)/K12 -> -0.064516129 | AP12: =+(M12-L12)/L12 -> 0.034482759 | AQ12: =+(N12-M12)/M12 -> 0.2 | AR12: =+(O12-N12)/N12 -> 0 | AS12: =+AVERAGE(AM12:AR12) -> 0.0093462901 | AT12: =+MEDIAN(AM12:AR12) -> 0.017241379 | AU12: =J12-I12 -> 4 | AV12: =K12-J12 -> -9 | AW12: =L12-K12 -> -2 | AX12: =M12-L12 -> 1 | AY12: =N12-M12 -> 6 | AZ12: =O12-N12 -> 0 | BA12: =+AVERAGE(AU12:AZ12) -> 0 | BB12: =MEDIAN(AU12:AZ12) -> 0.5 | BC12: =+(Q12-P12)/P12 -> 0.03125 | BD12: =+(R12-Q12)/Q12 -> 0.27272727 | BE12: =+(S12-R12)/R12 -> -0.21428571 | BF12: =+(T12-S12)/S12 -> -0.060606061 | BG12: =+(U12-T12)/T12 -> 0.12903226 | BH12: =+(V12-U12)/U12 -> -0.2 | BI12: =+AVERAGE(BC12:BH12) -> -0.006980374 | BJ12: =MEDIAN(BC12:BH12) -> -0.01467803 | BK12: =+Q12-P12 -> 1 | BL12: =+R12-Q12 -> 9 | BM12: =+S12-R12 -> -9 | BN12: =+T12-S12 -> -2 | BO12: =+U12-T12 -> 4 | BP12: =+V12-U12 -> -7 | BQ12: =+AVERAGE(BK12:BP12) -> -0.66666667 | BR12: =MEDIAN(BK12:BP12) -> -0.5
A13: 11 | B13: 72 | C13: 89 | D13: 87 | E13: 64 | F13: 80 | G13: 68 | H13: 76 | I13: 40 | J13: 43 | K13: 42 | L13: 27 | M13: 39 | N13: 34 | O13: 43 | P13: 32 | Q13: 46 | R13: 45 | S13: 37 | T13: 41 | U13: 34 | V13: 33 | W13: =+(C13-B13)/B13 -> 0.23611111 | X13: =+(D13-C13)/C13 -> -0.02247191 | Y13: =+(E13-D13)/D13 -> -0.26436782 | Z13: =+(F13-E13)/E13 -> 0.25 | AA13: =+(G13-F13)/F13 -> -0.15 | AB13: =+(H13-G13)/G13 -> 0.11764706 | AC13: =+AVERAGE(W13:AB13) -> 0.027819741 | AD13: =MEDIAN(W13:AB13) -> 0.047587574 | AE13: =C13-B13 -> 17 | AF13: =D13-C13 -> -2 | AG13: =E13-D13 -> -23 | AH13: =F13-E13 -> 16 | AI13: =G13-F13 -> -12 | AJ13: =H13-G13 -> 8 | AK13: =+AVERAGE(AE13:AJ13) -> 0.66666667 | AL13: =+MEDIAN(AE13:AJ13) -> 3 | AM13: =+(J13-I13)/I13 -> 0.075 | AN13: =+(K13-J13)/J13 -> -0.023255814 | AO13: =+(L13-K13)/K13 -> -0.35714286 | AP13: =+(M13-L13)/L13 -> 0.44444444 | AQ13: =+(N13-M13)/M13 -> -0.12820513 | AR13: =+(O13-N13)/N13 -> 0.26470588 | AS13: =+AVERAGE(AM13:AR13) -> 0.045924421 | AT13: =+MEDIAN(AM13:AR13) -> 0.025872093 | AU13: =J13-I13 -> 3 | AV13: =K13-J13 -> -1 | AW13: =L13-K13 -> -15 | AX13: =M13-L13 -> 12 | AY13: =N13-M13 -> -5 | AZ13: =O13-N13 -> 9 | BA13: =+AVERAGE(AU13:AZ13) -> 0.5 | BB13: =MEDIAN(AU13:AZ13) -> 1 | BC13: =+(Q13-P13)/P13 -> 0.4375 | BD13: =+(R13-Q13)/Q13 -> -0.02173913 | BE13: =+(S13-R13)/R13 -> -0.17777778 | BF13: =+(T13-S13)/S13 -> 0.10810811 | BG13: =+(U13-T13)/T13 -> -0.17073171 | BH13: =+(V13-U13)/U13 -> -0.029411765 | BI13: =+AVERAGE(BC13:BH13) -> 0.024324621 | BJ13: =MEDIAN(BC13:BH13) -> -0.025575448 | BK13: =+Q13-P13 -> 14 | BL13: =+R13-Q13 -> -1 | BM13: =+S13-R13 -> -8 | BN13: =+T13-S13 -> 4 | BO13: =+U13-T13 -> -7 | BP13: =+V13-U13 -> -1 | BQ13: =+AVERAGE(BK13:BP13) -> 0.16666667 | BR13: =MEDIAN(BK13:BP13) -> -1
... A109: 107 | B109: 15 | C109: 18 | D109: 19 | E109: 15 | F109: 18 | G109: 13 | H109: 10 | I109: 6 | J109: 8 | K109: 7 | L109: 4 | M109: 3 | N109: 4 | O109: 2 | P109: 9 | Q109: 10 | R109: 12 | S109: 11 | T109: 15 | U109: 9 | V109: 8 | W109: =+(C109-B109)/B109 -> 0.2 | X109: =+(D109-C109)/C109 -> 0.055555556 | Y109: =+(E109-D109)/D109 -> -0.21052632 | Z109: =+(F109-E109)/E109 -> 0.2 | AA109: =+(G109-F109)/F109 -> -0.27777778 | AB109: =+(H109-G109)/G109 -> -0.23076923 | AC109: =+AVERAGE(W109:AB109) -> -0.043919628 | AD109: =MEDIAN(W109:AB109) -> -0.07748538 | AE109: =C109-B109 -> 3 | AF109: =D109-C109 -> 1 | AG109: =E109-D109 -> -4 | AH109: =F109-E109 -> 3 | AI109: =G109-F109 -> -5 | AJ109: =H109-G109 -> -3 | AK109: =+AVERAGE(AE109:AJ109) -> -0.83333333 | AL109: =+MEDIAN(AE109:AJ109) -> -1 | AM109: =+(J109-I109)/I109 -> 0.33333333 | AN109: =+(K109-J109)/J109 -> -0.125 | AO109: =+(L109-K109)/K109 -> -0.42857143 | AP109: =+(M109-L109)/L109 -> -0.25 | AQ109: =+(N109-M109)/M109 -> 0.33333333 | AR109: =+(O109-N109)/N109 -> -0.5 | AS109: =+AVERAGE(AM109:AR109) -> -0.10615079 | AT109: =+MEDIAN(AM109:AR109) -> -0.1875 | AU109: =J109-I109 -> 2 | AV109: =K109-J109 -> -1 | AW109: =L109-K109 -> -3 | AX109: =M109-L109 -> -1 | AY109: =N109-M109 -> 1 | AZ109: =O109-N109 -> -2 | BA109: =+AVERAGE(AU109:AZ109) -> -0.66666667 | BB109: =MEDIAN(AU109:AZ109) -> -1 | BC109: =+(Q109-P109)/P109 -> 0.11111111 | BD109: =+(R109-Q109)/Q109 -> 0.2 | BE109: =+(S109-R109)/R109 -> -0.083333333 | BF109: =+(T109-S109)/S109 -> 0.36363636 | BG109: =+(U109-T109)/T109 -> -0.4 | BH109: =+(V109-U109)/U109 -> -0.11111111 | BI109: =+AVERAGE(BC109:BH109) -> 0.013383838 | BJ109: =MEDIAN(BC109:BH109) -> 0.013888889 | BK109: =+Q109-P109 -> 1 | BL109: =+R109-Q109 -> 2 | BM109: =+S109-R109 -> -1 | BN109: =+T109-S109 -> 4 | BO109: =+U109-T109 -> -6 | BP109: =+V109-U109 -> -1 | BQ109: =+AVERAGE(BK109:BP109) -> -0.16666667 | BR109: =MEDIAN(BK109:BP109) -> 0
A110: 108 | B110: 4 | C110: 7 | D110: 12 | E110: 5 | F110: 6 | G110: 7 | H110: 8 | I110: 3 | J110: 5 | K110: 3 | L110: 2 | N110: 3 | O110: 2 | P110: 1 | Q110: 2 | R110: 9 | S110: 3 | T110: 6 | U110: 4 | V110: 6 | W110: =+(C110-B110)/B110 -> 0.75 | X110: =+(D110-C110)/C110 -> 0.71428571 | Y110: =+(E110-D110)/D110 -> -0.58333333 | Z110: =+(F110-E110)/E110 -> 0.2 | AA110: =+(G110-F110)/F110 -> 0.16666667 | AB110: =+(H110-G110)/G110 -> 0.14285714 | AC110: =+AVERAGE(W110:AB110) -> 0.23174603 | AD110: =MEDIAN(W110:AB110) -> 0.18333333 | AE110: =C110-B110 -> 3 | AF110: =D110-C110 -> 5 | AG110: =E110-D110 -> -7 | AH110: =F110-E110 -> 1 | AI110: =G110-F110 -> 1 | AJ110: =H110-G110 -> 1 | AK110: =+AVERAGE(AE110:AJ110) -> 0.66666667 | AL110: =+MEDIAN(AE110:AJ110) -> 1 | AM110: =+(J110-I110)/I110 -> 0.66666667 | AN110: =+(K110-J110)/J110 -> -0.4 | AO110: =+(L110-K110)/K110 -> -0.33333333 | AP110: =+(M110-L110)/L110 -> -1 | AQ110: =+(N110-M110)/M110 -> #DIV/0! | AR110: =+(O110-N110)/N110 -> -0.33333333 | AS110: =+AVERAGE(AM110:AR110) -> #DIV/0! | AT110: =+MEDIAN(AM110:AR110) -> #DIV/0! | AU110: =J110-I110 -> 2 | AV110: =K110-J110 -> -2 | AW110: =L110-K110 -> -1 | AX110: =M110-L110 -> -2 | AY110: =N110-M110 -> 3 | AZ110: =O110-N110 -> -1 | BA110: =+AVERAGE(AU110:AZ110) -> -0.16666667 | BB110: =MEDIAN(AU110:AZ110) -> -1 | BC110: =+(Q110-P110)/P110 -> 1 | BD110: =+(R110-Q110)/Q110 -> 3.5 | BE110: =+(S110-R110)/R110 -> -0.66666667 | BF110: =+(T110-S110)/S110 -> 1 | BG110: =+(U110-T110)/T110 -> -0.33333333 | BH110: =+(V110-U110)/U110 -> 0.5 | BI110: =+AVERAGE(BC110:BH110) -> 0.83333333 | BJ110: =MEDIAN(BC110:BH110) -> 0.75 | BK110: =+Q110-P110 -> 1 | BL110: =+R110-Q110 -> 7 | BM110: =+S110-R110 -> -6 | BN110: =+T110-S110 -> 3 | BO110: =+U110-T110 -> -2 | BP110: =+V110-U110 -> 2 | BQ110: =+AVERAGE(BK110:BP110) -> 0.83333333 | BR110: =MEDIAN(BK110:BP110) -> 1.5
A111: 109 | C111: 7 | D111: 2 | E111: 6 | F111: 4 | G111: 7 | H111: 7 | J111: 2 | K111: 2 | L111: 3 | M111: 1 | N111: 2 | O111: 1 | Q111: 5 | S111: 3 | T111: 3 | U111: 5 | V111: 6 | W111: =+(C111-B111)/B111 -> #DIV/0! | X111: =+(D111-C111)/C111 -> -0.71428571 | Y111: =+(E111-D111)/D111 -> 2 | Z111: =+(F111-E111)/E111 -> -0.33333333 | AA111: =+(G111-F111)/F111 -> 0.75 | AB111: =+(H111-G111)/G111 -> 0 | AC111: =+AVERAGE(W111:AB111) -> #DIV/0! | AD111: =MEDIAN(W111:AB111) -> #DIV/0! | AE111: =C111-B111 -> 7 | AF111: =D111-C111 -> -5 | AG111: =E111-D111 -> 4 | AH111: =F111-E111 -> -2 | AI111: =G111-F111 -> 3 | AJ111: =H111-G111 -> 0 | AK111: =+AVERAGE(AE111:AJ111) -> 1.1666667 | AL111: =+MEDIAN(AE111:AJ111) -> 1.5 | AM111: =+(J111-I111)/I111 -> #DIV/0! | AN111: =+(K111-J111)/J111 -> 0 | AO111: =+(L111-K111)/K111 -> 0.5 | AP111: =+(M111-L111)/L111 -> -0.66666667 | AQ111: =+(N111-M111)/M111 -> 1 | AR111: =+(O111-N111)/N111 -> -0.5 | AS111: =+AVERAGE(AM111:AR111) -> #DIV/0! | AT111: =+MEDIAN(AM111:AR111) -> #DIV/0! | AU111: =J111-I111 -> 2 | AV111: =K111-J111 -> 0 | AW111: =L111-K111 -> 1 | AX111: =M111-L111 -> -2 | AY111: =N111-M111 -> 1 | AZ111: =O111-N111 -> -1 | BA111: =+AVERAGE(AU111:AZ111) -> 0.16666667 | BB111: =MEDIAN(AU111:AZ111) -> 0.5 | BC111: =+(Q111-P111)/P111 -> #DIV/0! | BD111: =+(R111-Q111)/Q111 -> -1 | BE111: =+(S111-R111)/R111 -> #DIV/0! | BF111: =+(T111-S111)/S111 -> 0 | BG111: =+(U111-T111)/T111 -> 0.66666667 | BH111: =+(V111-U111)/U111 -> 0.2 | BI111: =+AVERAGE(BC111:BH111) -> #DIV/0! | BJ111: =MEDIAN(BC111:BH111) -> #DIV/0! | BK111: =+Q111-P111 -> 5 | BL111: =+R111-Q111 -> -5 | BM111: =+S111-R111 -> 3 | BN111: =+T111-S111 -> 0 | BO111: =+U111-T111 -> 2 | BP111: =+V111-U111 -> 1 | BQ111: =+AVERAGE(BK111:BP111) -> 1 | BR111: =MEDIAN(BK111:BP111) -> 1.5
A112: 110 | B112: 5 | C112: 1 | D112: 1 | E112: 7 | F112: 5 | G112: 4 | H112: 4 | I112: 1 | K112: 1 | L112: 3 | M112: 2 | N112: 1 | P112: 4 | Q112: 1 | S112: 4 | T112: 3 | U112: 3 | V112: 4 | W112: =+(C112-B112)/B112 -> -0.8 | X112: =+(D112-C112)/C112 -> 0 | Y112: =+(E112-D112)/D112 -> 6 | Z112: =+(F112-E112)/E112 -> -0.28571429 | AA112: =+(G112-F112)/F112 -> -0.2 | AB112: =+(H112-G112)/G112 -> 0 | AC112: =+AVERAGE(W112:AB112) -> 0.78571429 | AD112: =MEDIAN(W112:AB112) -> -0.1 | AE112: =C112-B112 -> -4 | AF112: =D112-C112 -> 0 | AG112: =E112-D112 -> 6 | AH112: =F112-E112 -> -2 | AI112: =G112-F112 -> -1 | AJ112: =H112-G112 -> 0 | AK112: =+AVERAGE(AE112:AJ112) -> -0.16666667 | AL112: =+MEDIAN(AE112:AJ112) -> -0.5 | AM112: =+(J112-I112)/I112 -> -1 | AN112: =+(K112-J112)/J112 -> #DIV/0! | AO112: =+(L112-K112)/K112 -> 2 | AP112: =+(M112-L112)/L112 -> -0.33333333 | AQ112: =+(N112-M112)/M112 -> -0.5 | AR112: =+(O112-N112)/N112 -> -1 | AS112: =+AVERAGE(AM112:AR112) -> #DIV/0! | AT112: =+MEDIAN(AM112:AR112) -> #DIV/0! | AU112: =J112-I112 -> -1 | AV112: =K112-J112 -> 1 | AW112: =L112-K112 -> 2 | AX112: =M112-L112 -> -1 | AY112: =N112-M112 -> -1 | AZ112: =O112-N112 -> -1 | BA112: =+AVERAGE(AU112:AZ112) -> -0.16666667 | BB112: =MEDIAN(AU112:AZ112) -> -1 | BC112: =+(Q112-P112)/P112 -> -0.75 | BD112: =+(R112-Q112)/Q112 -> -1 | BE112: =+(S112-R112)/R112 -> #DIV/0! | BF112: =+(T112-S112)/S112 -> -0.25 | BG112: =+(U112-T112)/T112 -> 0 | BH112: =+(V112-U112)/U112 -> 0.33333333 | BI112: =+AVERAGE(BC112:BH112) -> #DIV/0! | BJ112: =MEDIAN(BC112:BH112) -> #DIV/0! | BK112: =+Q112-P112 -> -3 | BL112: =+R112-Q112 -> -1 | BM112: =+S112-R112 -> 4 | BN112: =+T112-S112 -> -1 | BO112: =+U112-T112 -> 0 | BP112: =+V112-U112 -> 1 | BQ112: =+AVERAGE(BK112:BP112) -> 0 | BR112: =MEDIAN(BK112:BP112) -> -0.5
A113: 111 | B113: 2 | C113: 3 | D113: 2 | E113: 3 | G113: 1 | H113: 2 | I113: 1 | J113: 2 | P113: 1 | Q113: 1 | R113: 2 | S113: 3 | U113: 1 | V113: 2 | W113: =+(C113-B113)/B113 -> 0.5 | X113: =+(D113-C113)/C113 -> -0.33333333 | Y113: =+(E113-D113)/D113 -> 0.5 | Z113: =+(F113-E113)/E113 -> -1 | AA113: =+(G113-F113)/F113 -> #DIV/0! | AB113: =+(H113-G113)/G113 -> 1 | AC113: =+AVERAGE(W113:AB113) -> #DIV/0! | AD113: =MEDIAN(W113:AB113) -> #DIV/0! | AE113: =C113-B113 -> 1 | AF113: =D113-C113 -> -1 | AG113: =E113-D113 -> 1 | AH113: =F113-E113 -> -3 | AI113: =G113-F113 -> 1 | AJ113: =H113-G113 -> 1 | AK113: =+AVERAGE(AE113:AJ113) -> 0 | AL113: =+MEDIAN(AE113:AJ113) -> 1 | AM113: =+(J113-I113)/I113 -> 1 | AN113: =+(K113-J113)/J113 -> -1 | AO113: =+(L113-K113)/K113 -> #DIV/0! | AP113: =+(M113-L113)/L113 -> #DIV/0! | AQ113: =+(N113-M113)/M113 -> #DIV/0! | AR113: =+(O113-N113)/N113 -> #DIV/0! | AS113: =+AVERAGE(AM113:AR113) -> #DIV/0! | AT113: =+MEDIAN(AM113:AR113) -> #DIV/0! | AU113: =J113-I113 -> 1 | AV113: =K113-J113 -> -2 | AW113: =L113-K113 -> 0 | AX113: =M113-L113 -> 0 | AY113: =N113-M113 -> 0 | AZ113: =O113-N113 -> 0 | BA113: =+AVERAGE(AU113:AZ113) -> -0.16666667 | BB113: =MEDIAN(AU113:AZ113) -> 0 | BC113: =+(Q113-P113)/P113 -> 0 | BD113: =+(R113-Q113)/Q113 -> 1 | BE113: =+(S113-R113)/R113 -> 0.5 | BF113: =+(T113-S113)/S113 -> -1 | BG113: =+(U113-T113)/T113 -> #DIV/0! | BH113: =+(V113-U113)/U113 -> 1 | BI113: =+AVERAGE(BC113:BH113) -> #DIV/0! | BJ113: =MEDIAN(BC113:BH113) -> #DIV/0! | BK113: =+Q113-P113 -> 0 | BL113: =+R113-Q113 -> 1 | BM113: =+S113-R113 -> 1 | BN113: =+T113-S113 -> -3 | BO113: =+U113-T113 -> 1 | BP113: =+V113-U113 -> 1 | BQ113: =+AVERAGE(BK113:BP113) -> 0.16666667 | BR113: =MEDIAN(BK113:BP113) -> 1
A114: 112 | D114: 1 | E114: 1 | F114: 1 | G114: 1 | H114: 2 | N114: 1 | R114: 1 | S114: 1 | T114: 1 | V114: 2 | W114: =+(C114-B114)/B114 -> #DIV/0! | X114: =+(D114-C114)/C114 -> #DIV/0! | Y114: =+(E114-D114)/D114 -> 0 | Z114: =+(F114-E114)/E114 -> 0 | AA114: =+(G114-F114)/F114 -> 0 | AB114: =+(H114-G114)/G114 -> 1 | AC114: =+AVERAGE(W114:AB114) -> #DIV/0! | AD114: =MEDIAN(W114:AB114) -> #DIV/0! | AE114: =C114-B114 -> 0 | AF114: =D114-C114 -> 1 | AG114: =E114-D114 -> 0 | AH114: =F114-E114 -> 0 | AI114: =G114-F114 -> 0 | AJ114: =H114-G114 -> 1 | AK114: =+AVERAGE(AE114:AJ114) -> 0.33333333 | AL114: =+MEDIAN(AE114:AJ114) -> 0 | AM114: =+(J114-I114)/I114 -> #DIV/0! | AN114: =+(K114-J114)/J114 -> #DIV/0! | AO114: =+(L114-K114)/K114 -> #DIV/0! | AP114: =+(M114-L114)/L114 -> #DIV/0! | AQ114: =+(N114-M114)/M114 -> #DIV/0! | AR114: =+(O114-N114)/N114 -> -1 | AS114: =+AVERAGE(AM114:AR114) -> #DIV/0! | AT114: =+MEDIAN(AM114:AR114) -> #DIV/0! | AU114: =J114-I114 -> 0 | AV114: =K114-J114 -> 0 | AW114: =L114-K114 -> 0 | AX114: =M114-L114 -> 0 | AY114: =N114-M114 -> 1 | AZ114: =O114-N114 -> -1 | BA114: =+AVERAGE(AU114:AZ114) -> 0 | BB114: =MEDIAN(AU114:AZ114) -> 0 | BC114: =+(Q114-P114)/P114 -> #DIV/0! | BD114: =+(R114-Q114)/Q114 -> #DIV/0! | BE114: =+(S114-R114)/R114 -> 0 | BF114: =+(T114-S114)/S114 -> 0 | BG114: =+(U114-T114)/T114 -> -1 | BH114: =+(V114-U114)/U114 -> #DIV/0! | BI114: =+AVERAGE(BC114:BH114) -> #DIV/0! | BJ114: =MEDIAN(BC114:BH114) -> #DIV/0! | BK114: =+Q114-P114 -> 0 | BL114: =+R114-Q114 -> 1 | BM114: =+S114-R114 -> 0 | BN114: =+T114-S114 -> 0 | BO114: =+U114-T114 -> -1 | BP114: =+V114-U114 -> 2 | BQ114: =+AVERAGE(BK114:BP114) -> 0.33333333 | BR114: =MEDIAN(BK114:BP114) -> 0
A115: 113 | B115: 1 | C115: 1 | D115: 3 | E115: 2 | G115: 2 | H115: 1 | I115: 1 | K115: 1 | L115: 1 | N115: 1 | Q115: 1 | R115: 2 | S115: 1 | U115: 1 | V115: 1 | W115: =+(C115-B115)/B115 -> 0 | X115: =+(D115-C115)/C115 -> 2 | Y115: =+(E115-D115)/D115 -> -0.33333333 | Z115: =+(F115-E115)/E115 -> -1 | AA115: =+(G115-F115)/F115 -> #DIV/0! | AB115: =+(H115-G115)/G115 -> -0.5 | AC115: =+AVERAGE(W115:AB115) -> #DIV/0! | AD115: =MEDIAN(W115:AB115) -> #DIV/0! | AE115: =C115-B115 -> 0 | AF115: =D115-C115 -> 2 | AG115: =E115-D115 -> -1 | AH115: =F115-E115 -> -2 | AI115: =G115-F115 -> 2 | AJ115: =H115-G115 -> -1 | AK115: =+AVERAGE(AE115:AJ115) -> 0 | AL115: =+MEDIAN(AE115:AJ115) -> -0.5 | AM115: =+(J115-I115)/I115 -> -1 | AN115: =+(K115-J115)/J115 -> #DIV/0! | AO115: =+(L115-K115)/K115 -> 0 | AP115: =+(M115-L115)/L115 -> -1 | AQ115: =+(N115-M115)/M115 -> #DIV/0! | AR115: =+(O115-N115)/N115 -> -1 | AS115: =+AVERAGE(AM115:AR115) -> #DIV/0! | AT115: =+MEDIAN(AM115:AR115) -> #DIV/0! | AU115: =J115-I115 -> -1 | AV115: =K115-J115 -> 1 | AW115: =L115-K115 -> 0 | AX115: =M115-L115 -> -1 | AY115: =N115-M115 -> 1 | AZ115: =O115-N115 -> -1 | BA115: =+AVERAGE(AU115:AZ115) -> -0.16666667 | BB115: =MEDIAN(AU115:AZ115) -> -0.5 | BC115: =+(Q115-P115)/P115 -> #DIV/0! | BD115: =+(R115-Q115)/Q115 -> 1 | BE115: =+(S115-R115)/R115 -> -0.5 | BF115: =+(T115-S115)/S115 -> -1 | BG115: =+(U115-T115)/T115 -> #DIV/0! | BH115: =+(V115-U115)/U115 -> 0 | BI115: =+AVERAGE(BC115:BH115) -> #DIV/0! | BJ115: =MEDIAN(BC115:BH115) -> #DIV/0! | BK115: =+Q115-P115 -> 1 | BL115: =+R115-Q115 -> 1 | BM115: =+S115-R115 -> -1 | BN115: =+T115-S115 -> -1 | BO115: =+U115-T115 -> 1 | BP115: =+V115-U115 -> 0 | BQ115: =+AVERAGE(BK115:BP115) -> 0.16666667 | BR115: =MEDIAN(BK115:BP115) -> 0.5
A116: 114 | B116: 1 | E116: 3 | L116: 3 | P116: 1 | W116: =+(C116-B116)/B116 -> -1 | X116: =+(D116-C116)/C116 -> #DIV/0! | Y116: =+(E116-D116)/D116 -> #DIV/0! | Z116: =+(F116-E116)/E116 -> -1 | AA116: =+(G116-F116)/F116 -> #DIV/0! | AB116: =+(H116-G116)/G116 -> #DIV/0! | AC116: =+AVERAGE(W116:AB116) -> #DIV/0! | AD116: =MEDIAN(W116:AB116) -> #DIV/0! | AE116: =C116-B116 -> -1 | AF116: =D116-C116 -> 0 | AG116: =E116-D116 -> 3 | AH116: =F116-E116 -> -3 | AI116: =G116-F116 -> 0 | AJ116: =H116-G116 -> 0 | AK116: =+AVERAGE(AE116:AJ116) -> -0.16666667 | AL116: =+MEDIAN(AE116:AJ116) -> 0 | AM116: =+(J116-I116)/I116 -> #DIV/0! | AN116: =+(K116-J116)/J116 -> #DIV/0! | AO116: =+(L116-K116)/K116 -> #DIV/0! | AP116: =+(M116-L116)/L116 -> -1 | AQ116: =+(N116-M116)/M116 -> #DIV/0! | AR116: =+(O116-N116)/N116 -> #DIV/0! | AS116: =+AVERAGE(AM116:AR116) -> #DIV/0! | AT116: =+MEDIAN(AM116:AR116) -> #DIV/0! | AU116: =J116-I116 -> 0 | AV116: =K116-J116 -> 0 | AW116: =L116-K116 -> 3 | AX116: =M116-L116 -> -3 | AY116: =N116-M116 -> 0 | AZ116: =O116-N116 -> 0 | BA116: =+AVERAGE(AU116:AZ116) -> 0 | BB116: =MEDIAN(AU116:AZ116) -> 0 | BC116: =+(Q116-P116)/P116 -> -1 | BD116: =+(R116-Q116)/Q116 -> #DIV/0! | BE116: =+(S116-R116)/R116 -> #DIV/0! | BF116: =+(T116-S116)/S116 -> #DIV/0! | BG116: =+(U116-T116)/T116 -> #DIV/0! | BH116: =+(V116-U116)/U116 -> #DIV/0! | BI116: =+AVERAGE(BC116:BH116) -> #DIV/0! | BJ116: =MEDIAN(BC116:BH116) -> #DIV/0! | BK116: =+Q116-P116 -> -1 | BL116: =+R116-Q116 -> 0 | BM116: =+S116-R116 -> 0 | BN116: =+T116-S116 -> 0 | BO116: =+U116-T116 -> 0 | BP116: =+V116-U116 -> 0 | BQ116: =+AVERAGE(BK116:BP116) -> -0.16666667 | BR116: =MEDIAN(BK116:BP116) -> 0
A117: 115 | D117: 1 | G117: 1 | N117: 1 | R117: 1 | W117: =+(C117-B117)/B117 -> #DIV/0! | X117: =+(D117-C117)/C117 -> #DIV/0! | Y117: =+(E117-D117)/D117 -> -1 | Z117: =+(F117-E117)/E117 -> #DIV/0! | AA117: =+(G117-F117)/F117 -> #DIV/0! | AB117: =+(H117-G117)/G117 -> -1 | AC117: =+AVERAGE(W117:AB117) -> #DIV/0! | AD117: =MEDIAN(W117:AB117) -> #DIV/0! | AE117: =C117-B117 -> 0 | AF117: =D117-C117 -> 1 | AG117: =E117-D117 -> -1 | AH117: =F117-E117 -> 0 | AI117: =G117-F117 -> 1 | AJ117: =H117-G117 -> -1 | AK117: =+AVERAGE(AE117:AJ117) -> 0 | AL117: =+MEDIAN(AE117:AJ117) -> 0 | AM117: =+(J117-I117)/I117 -> #DIV/0! | AN117: =+(K117-J117)/J117 -> #DIV/0! | AO117: =+(L117-K117)/K117 -> #DIV/0! | AP117: =+(M117-L117)/L117 -> #DIV/0! | AQ117: =+(N117-M117)/M117 -> #DIV/0! | AR117: =+(O117-N117)/N117 -> -1 | AS117: =+AVERAGE(AM117:AR117) -> #DIV/0! | AT117: =+MEDIAN(AM117:AR117) -> #DIV/0! | AU117: =J117-I117 -> 0 | AV117: =K117-J117 -> 0 | AW117: =L117-K117 -> 0 | AX117: =M117-L117 -> 0 | AY117: =N117-M117 -> 1 | AZ117: =O117-N117 -> -1 | BA117: =+AVERAGE(AU117:AZ117) -> 0 | BB117: =MEDIAN(AU117:AZ117) -> 0 | BC117: =+(Q117-P117)/P117 -> #DIV/0! | BD117: =+(R117-Q117)/Q117 -> #DIV/0! | BE117: =+(S117-R117)/R117 -> -1 | BF117: =+(T117-S117)/S117 -> #DIV/0! | BG117: =+(U117-T117)/T117 -> #DIV/0! | BH117: =+(V117-U117)/U117 -> #DIV/0! | BI117: =+AVERAGE(BC117:BH117) -> #DIV/0! | BJ117: =MEDIAN(BC117:BH117) -> #DIV/0! | BK117: =+Q117-P117 -> 0 | BL117: =+R117-Q117 -> 1 | BM117: =+S117-R117 -> -1 | BN117: =+T117-S117 -> 0 | BO117: =+U117-T117 -> 0 | BP117: =+V117-U117 -> 0 | BQ117: =+AVERAGE(BK117:BP117) -> 0 | BR117: =MEDIAN(BK117:BP117) -> 0
A118: 116 | B118: 2 | E118: 1 | I118: 1 | L118: 1 | P118: 1 | W118: =+(C118-B118)/B118 -> -1 | X118: =+(D118-C118)/C118 -> #DIV/0! | Y118: =+(E118-D118)/D118 -> #DIV/0! | Z118: =+(F118-E118)/E118 -> -1 | AA118: =+(G118-F118)/F118 -> #DIV/0! | AB118: =+(H118-G118)/G118 -> #DIV/0! | AC118: =+AVERAGE(W118:AB118) -> #DIV/0! | AD118: =MEDIAN(W118:AB118) -> #DIV/0! | AE118: =C118-B118 -> -2 | AF118: =D118-C118 -> 0 | AG118: =E118-D118 -> 1 | AH118: =F118-E118 -> -1 | AI118: =G118-F118 -> 0 | AJ118: =H118-G118 -> 0 | AK118: =+AVERAGE(AE118:AJ118) -> -0.33333333 | AL118: =+MEDIAN(AE118:AJ118) -> 0 | AM118: =+(J118-I118)/I118 -> -1 | AN118: =+(K118-J118)/J118 -> #DIV/0! | AO118: =+(L118-K118)/K118 -> #DIV/0! | AP118: =+(M118-L118)/L118 -> -1 | AQ118: =+(N118-M118)/M118 -> #DIV/0! | AR118: =+(O118-N118)/N118 -> #DIV/0! | AS118: =+AVERAGE(AM118:AR118) -> #DIV/0! | AT118: =+MEDIAN(AM118:AR118) -> #DIV/0! | AU118: =J118-I118 -> -1 | AV118: =K118-J118 -> 0 | AW118: =L118-K118 -> 1 | AX118: =M118-L118 -> -1 | AY118: =N118-M118 -> 0 | AZ118: =O118-N118 -> 0 | BA118: =+AVERAGE(AU118:AZ118) -> -0.16666667 | BB118: =MEDIAN(AU118:AZ118) -> 0 | BC118: =+(Q118-P118)/P118 -> -1 | BD118: =+(R118-Q118)/Q118 -> #DIV/0! | BE118: =+(S118-R118)/R118 -> #DIV/0! | BF118: =+(T118-S118)/S118 -> #DIV/0! | BG118: =+(U118-T118)/T118 -> #DIV/0! | BH118: =+(V118-U118)/U118 -> #DIV/0! | BI118: =+AVERAGE(BC118:BH118) -> #DIV/0! | BJ118: =MEDIAN(BC118:BH118) -> #DIV/0! | BK118: =+Q118-P118 -> -1 | BL118: =+R118-Q118 -> 0 | BM118: =+S118-R118 -> 0 | BN118: =+T118-S118 -> 0 | BO118: =+U118-T118 -> 0 | BP118: =+V118-U118 -> 0 | BQ118: =+AVERAGE(BK118:BP118) -> -0.16666667 | BR118: =MEDIAN(BK118:BP118) -> 0
A119: 117 | B119: 2 | E119: 1 | I119: 1 | L119: 1 | P119: 1 | W119: =+(C119-B119)/B119 -> -1 | X119: =+(D119-C119)/C119 -> #DIV/0! | Y119: =+(E119-D119)/D119 -> #DIV/0! | Z119: =+(F119-E119)/E119 -> -1 | AA119: =+(G119-F119)/F119 -> #DIV/0! | AB119: =+(H119-G119)/G119 -> #DIV/0! | AC119: =+AVERAGE(W119:AB119) -> #DIV/0! | AD119: =MEDIAN(W119:AB119) -> #DIV/0! | AE119: =C119-B119 -> -2 | AF119: =D119-C119 -> 0 | AG119: =E119-D119 -> 1 | AH119: =F119-E119 -> -1 | AI119: =G119-F119 -> 0 | AJ119: =H119-G119 -> 0 | AK119: =+AVERAGE(AE119:AJ119) -> -0.33333333 | AL119: =+MEDIAN(AE119:AJ119) -> 0 | AM119: =+(J119-I119)/I119 -> -1 | AN119: =+(K119-J119)/J119 -> #DIV/0! | AO119: =+(L119-K119)/K119 -> #DIV/0! | AP119: =+(M119-L119)/L119 -> -1 | AQ119: =+(N119-M119)/M119 -> #DIV/0! | AR119: =+(O119-N119)/N119 -> #DIV/0! | AS119: =+AVERAGE(AM119:AR119) -> #DIV/0! | AT119: =+MEDIAN(AM119:AR119) -> #DIV/0! | AU119: =J119-I119 -> -1 | AV119: =K119-J119 -> 0 | AW119: =L119-K119 -> 1 | AX119: =M119-L119 -> -1 | AY119: =N119-M119 -> 0 | AZ119: =O119-N119 -> 0 | BA119: =+AVERAGE(AU119:AZ119) -> -0.16666667 | BB119: =MEDIAN(AU119:AZ119) -> 0 | BC119: =+(Q119-P119)/P119 -> -1 | BD119: =+(R119-Q119)/Q119 -> #DIV/0! | BE119: =+(S119-R119)/R119 -> #DIV/0! | BF119: =+(T119-S119)/S119 -> #DIV/0! | BG119: =+(U119-T119)/T119 -> #DIV/0! | BH119: =+(V119-U119)/U119 -> #DIV/0! | BI119: =+AVERAGE(BC119:BH119) -> #DIV/0! | BJ119: =MEDIAN(BC119:BH119) -> #DIV/0! | BK119: =+Q119-P119 -> -1 | BL119: =+R119-Q119 -> 0 | BM119: =+S119-R119 -> 0 | BN119: =+T119-S119 -> 0 | BO119: =+U119-T119 -> 0 | BP119: =+V119-U119 -> 0 | BQ119: =+AVERAGE(BK119:BP119) -> -0.16666667 | BR119: =MEDIAN(BK119:BP119) -> 0
A120: 118 | C120: 2 | D120: 1 | K120: 1 | Q120: 2 | W120: =+(C120-B120)/B120 -> #DIV/0! | X120: =+(D120-C120)/C120 -> -0.5 | Y120: =+(E120-D120)/D120 -> -1 | Z120: =+(F120-E120)/E120 -> #DIV/0! | AA120: =+(G120-F120)/F120 -> #DIV/0! | AB120: =+(H120-G120)/G120 -> #DIV/0! | AC120: =+AVERAGE(W120:AB120) -> #DIV/0! | AD120: =MEDIAN(W120:AB120) -> #DIV/0! | AE120: =C120-B120 -> 2 | AF120: =D120-C120 -> -1 | AG120: =E120-D120 -> -1 | AH120: =F120-E120 -> 0 | AI120: =G120-F120 -> 0 | AJ120: =H120-G120 -> 0 | AK120: =+AVERAGE(AE120:AJ120) -> 0 | AL120: =+MEDIAN(AE120:AJ120) -> 0 | AM120: =+(J120-I120)/I120 -> #DIV/0! | AN120: =+(K120-J120)/J120 -> #DIV/0! | AO120: =+(L120-K120)/K120 -> -1 | AP120: =+(M120-L120)/L120 -> #DIV/0! | AQ120: =+(N120-M120)/M120 -> #DIV/0! | AR120: =+(O120-N120)/N120 -> #DIV/0! | AS120: =+AVERAGE(AM120:AR120) -> #DIV/0! | AT120: =+MEDIAN(AM120:AR120) -> #DIV/0! | AU120: =J120-I120 -> 0 | AV120: =K120-J120 -> 1 | AW120: =L120-K120 -> -1 | AX120: =M120-L120 -> 0 | AY120: =N120-M120 -> 0 | AZ120: =O120-N120 -> 0 | BA120: =+AVERAGE(AU120:AZ120) -> 0 | BB120: =MEDIAN(AU120:AZ120) -> 0 | BC120: =+(Q120-P120)/P120 -> #DIV/0! | BD120: =+(R120-Q120)/Q120 -> -1 | BE120: =+(S120-R120)/R120 -> #DIV/0! | BF120: =+(T120-S120)/S120 -> #DIV/0! | BG120: =+(U120-T120)/T120 -> #DIV/0! | BH120: =+(V120-U120)/U120 -> #DIV/0! | BI120: =+AVERAGE(BC120:BH120) -> #DIV/0! | BJ120: =MEDIAN(BC120:BH120) -> #DIV/0! | BK120: =+Q120-P120 -> 2 | BL120: =+R120-Q120 -> -2 | BM120: =+S120-R120 -> 0 | BN120: =+T120-S120 -> 0 | BO120: =+U120-T120 -> 0 | BP120: =+V120-U120 -> 0 | BQ120: =+AVERAGE(BK120:BP120) -> 0 | BR120: =MEDIAN(BK120:BP120) -> 0
A121: 119 | D121: 1 | E121: 2 | K121: 1 | L121: 2 | W121: =+(C121-B121)/B121 -> #DIV/0! | X121: =+(D121-C121)/C121 -> #DIV/0! | Y121: =+(E121-D121)/D121 -> 1 | Z121: =+(F121-E121)/E121 -> -1 | AA121: =+(G121-F121)/F121 -> #DIV/0! | AB121: =+(H121-G121)/G121 -> #DIV/0! | AC121: =+AVERAGE(W121:AB121) -> #DIV/0! | AD121: =MEDIAN(W121:AB121) -> #DIV/0! | AE121: =C121-B121 -> 0 | AF121: =D121-C121 -> 1 | AG121: =E121-D121 -> 1 | AH121: =F121-E121 -> -2 | AI121: =G121-F121 -> 0 | AJ121: =H121-G121 -> 0 | AK121: =+AVERAGE(AE121:AJ121) -> 0 | AL121: =+MEDIAN(AE121:AJ121) -> 0 | AM121: =+(J121-I121)/I121 -> #DIV/0! | AN121: =+(K121-J121)/J121 -> #DIV/0! | AO121: =+(L121-K121)/K121 -> 1 | AP121: =+(M121-L121)/L121 -> -1 | AQ121: =+(N121-M121)/M121 -> #DIV/0! | AR121: =+(O121-N121)/N121 -> #DIV/0! | AS121: =+AVERAGE(AM121:AR121) -> #DIV/0! | AT121: =+MEDIAN(AM121:AR121) -> #DIV/0! | AU121: =J121-I121 -> 0 | AV121: =K121-J121 -> 1 | AW121: =L121-K121 -> 1 | AX121: =M121-L121 -> -2 | AY121: =N121-M121 -> 0 | AZ121: =O121-N121 -> 0 | BA121: =+AVERAGE(AU121:AZ121) -> 0 | BB121: =MEDIAN(AU121:AZ121) -> 0 | BC121: =+(Q121-P121)/P121 -> #DIV/0! | BD121: =+(R121-Q121)/Q121 -> #DIV/0! | BE121: =+(S121-R121)/R121 -> #DIV/0! | BF121: =+(T121-S121)/S121 -> #DIV/0! | BG121: =+(U121-T121)/T121 -> #DIV/0! | BH121: =+(V121-U121)/U121 -> #DIV/0! | BI121: =+AVERAGE(BC121:BH121) -> #DIV/0! | BJ121: =MEDIAN(BC121:BH121) -> #DIV/0! | BK121: =+Q121-P121 -> 0 | BL121: =+R121-Q121 -> 0 | BM121: =+S121-R121 -> 0 | BN121: =+T121-S121 -> 0 | BO121: =+U121-T121 -> 0 | BP121: =+V121-U121 -> 0 | BQ121: =+AVERAGE(BK121:BP121) -> 0 | BR121: =MEDIAN(BK121:BP121) -> 0
A122: 120 | F122: 2 | H122: 1 | M122: 2 | V122: 1 | W122: =+(C122-B122)/B122 -> #DIV/0! | X122: =+(D122-C122)/C122 -> #DIV/0! | Y122: =+(E122-D122)/D122 -> #DIV/0! | Z122: =+(F122-E122)/E122 -> #DIV/0! | AA122: =+(G122-F122)/F122 -> -1 | AB122: =+(H122-G122)/G122 -> #DIV/0! | AC122: =+AVERAGE(W122:AB122) -> #DIV/0! | AD122: =MEDIAN(W122:AB122) -> #DIV/0! | AE122: =C122-B122 -> 0 | AF122: =D122-C122 -> 0 | AG122: =E122-D122 -> 0 | AH122: =F122-E122 -> 2 | AI122: =G122-F122 -> -2 | AJ122: =H122-G122 -> 1 | AK122: =+AVERAGE(AE122:AJ122) -> 0.16666667 | AL122: =+MEDIAN(AE122:AJ122) -> 0 | AM122: =+(J122-I122)/I122 -> #DIV/0! | AN122: =+(K122-J122)/J122 -> #DIV/0! | AO122: =+(L122-K122)/K122 -> #DIV/0! | AP122: =+(M122-L122)/L122 -> #DIV/0! | AQ122: =+(N122-M122)/M122 -> -1 | AR122: =+(O122-N122)/N122 -> #DIV/0! | AS122: =+AVERAGE(AM122:AR122) -> #DIV/0! | AT122: =+MEDIAN(AM122:AR122) -> #DIV/0! | AU122: =J122-I122 -> 0 | AV122: =K122-J122 -> 0 | AW122: =L122-K122 -> 0 | AX122: =M122-L122 -> 2 | AY122: =N122-M122 -> -2 | AZ122: =O122-N122 -> 0 | BA122: =+AVERAGE(AU122:AZ122) -> 0 | BB122: =MEDIAN(AU122:AZ122) -> 0 | BC122: =+(Q122-P122)/P122 -> #DIV/0! | BD122: =+(R122-Q122)/Q122 -> #DIV/0! | BE122: =+(S122-R122)/R122 -> #DIV/0! | BF122: =+(T122-S122)/S122 -> #DIV/0! | BG122: =+(U122-T122)/T122 -> #DIV/0! | BH122: =+(V122-U122)/U122 -> #DIV/0! | BI122: =+AVERAGE(BC122:BH122) -> #DIV/0! | BJ122: =MEDIAN(BC122:BH122) -> #DIV/0! | BK122: =+Q122-P122 -> 0 | BL122: =+R122-Q122 -> 0 | BM122: =+S122-R122 -> 0 | BN122: =+T122-S122 -> 0 | BO122: =+U122-T122 -> 0 | BP122: =+V122-U122 -> 1 | BQ122: =+AVERAGE(BK122:BP122) -> 0.16666667 | BR122: =MEDIAN(BK122:BP122) -> 0
A123: 999 | B123: 1 | C123: 4 | D123: 28 | G123: 2 | H123: 2 | I123: 1 | J123: 4 | K123: 15 | O123: 2 | R123: 13 | U123: 2 | W123: =+(C123-B123)/B123 -> 3 | X123: =+(D123-C123)/C123 -> 6 | Y123: =+(E123-D123)/D123 -> -1 | Z123: =+(F123-E123)/E123 -> #DIV/0! | AA123: =+(G123-F123)/F123 -> #DIV/0! | AB123: =+(H123-G123)/G123 -> 0 | AC123: =+AVERAGE(W123:AB123) -> #DIV/0! | AD123: =MEDIAN(W123:AB123) -> #DIV/0! | AE123: =C123-B123 -> 3 | AF123: =D123-C123 -> 24 | AG123: =E123-D123 -> -28 | AH123: =F123-E123 -> 0 | AI123: =G123-F123 -> 2 | AJ123: =H123-G123 -> 0 | AK123: =+AVERAGE(AE123:AJ123) -> 0.16666667 | AL123: =+MEDIAN(AE123:AJ123) -> 1 | AM123: =+(J123-I123)/I123 -> 3 | AN123: =+(K123-J123)/J123 -> 2.75 | AO123: =+(L123-K123)/K123 -> -1 | AP123: =+(M123-L123)/L123 -> #DIV/0! | AQ123: =+(N123-M123)/M123 -> #DIV/0! | AR123: =+(O123-N123)/N123 -> #DIV/0! | AS123: =+AVERAGE(AM123:AR123) -> #DIV/0! | AT123: =+MEDIAN(AM123:AR123) -> #DIV/0! | AU123: =J123-I123 -> 3 | AV123: =K123-J123 -> 11 | AW123: =L123-K123 -> -15 | AX123: =M123-L123 -> 0 | AY123: =N123-M123 -> 0 | AZ123: =O123-N123 -> 2 | BA123: =+AVERAGE(AU123:AZ123) -> 0.16666667 | BB123: =MEDIAN(AU123:AZ123) -> 1 | BC123: =+(Q123-P123)/P123 -> #DIV/0! | BD123: =+(R123-Q123)/Q123 -> #DIV/0! | BE123: =+(S123-R123)/R123 -> -1 | BF123: =+(T123-S123)/S123 -> #DIV/0! | BG123: =+(U123-T123)/T123 -> #DIV/0! | BH123: =+(V123-U123)/U123 -> -1 | BI123: =+AVERAGE(BC123:BH123) -> #DIV/0! | BJ123: =MEDIAN(BC123:BH123) -> #DIV/0! | BK123: =+Q123-P123 -> 0 | BL123: =+R123-Q123 -> 13 | BM123: =+S123-R123 -> -13 | BN123: =+T123-S123 -> 0 | BO123: =+U123-T123 -> 2 | BP123: =+V123-U123 -> -2 | BQ123: =+AVERAGE(BK123:BP123) -> 0 | BR123: =MEDIAN(BK123:BP123) -> 0
B124: =SUBTOTAL(109,Tabla16[2017]) -> 51750 | C124: =SUBTOTAL(109,Tabla16[2018]) -> 53044 | D124: =SUBTOTAL(109,Tabla16[2019]) -> 55469 | E124: =SUBTOTAL(109,Tabla16[2020]) -> 73732 | F124: =SUBTOTAL(109,Tabla16[2021]) -> 64945 | G124: =SUBTOTAL(109,Tabla16[2022]) -> 65325 | H124: =SUBTOTAL(109,Tabla16[2023]) -> 63161

Sheet provincia
A1: prov_res | B1: 2017 | C1: Hombres_2017 | D1: Mujeres_2017 | E1: 2018 | F1: Hombres_2018 | G1: Mujeres_2018 | H1: 2019 | I1: Hombres_2019 | J1: Mujeres_2019 | K1: 2020 | L1: Hombres_2020 | M1: Mujeres_2020 | N1: 2021 | O1: Hombres_2021 | P1: Mujeres_2021 | Q1: 2022 | R1: Hombres_2022 | S1: Mujeres_2022 | T1: 2023 | U1: Hombres_2023 | V1: Mujeres_2023
A2: 09 | B2: 15503 | C2: 8132 | D2: 7371 | E2: 15014 | F2: 7777 | G2: 7237 | H2: 15912 | I2: 8305 | J2: 7607 | K2: 27460 | L2: 15682 | M2: 11778 | N2: 18550 | O2: 9750 | P2: 8800 | Q2: 18872 | R2: 9834 | S2: 9038 | T2: 17738 | U2: 9256 | V2: 8482
A3: 17 | B3: 8873 | C3: 4333 | D3: 4540 | E3: 9304 | F3: 4486 | G3: 4818 | H3: 9414 | I3: 4509 | J3: 4905 | K3: 10717 | L3: 5376 | M3: 5341 | N3: 10694 | O3: 5378 | P3: 5316 | Q3: 10580 | R3: 5176 | S3: 5404 | T3: 10466 | U3: 5099 | V3: 5367
A4: 13 | B4: 5279 | C4: 2843 | D4: 2436 | E4: 5462 | F4: 2955 | G4: 2507 | H4: 5721 | I4: 3127 | J4: 2594 | K4: 7220 | L4: 4051 | M4: 3169 | N4: 6431 | O4: 3475 | P4: 2956 | Q4: 6640 | R4: 3562 | S4: 3078 | T4: 6141 | U4: 3304 | V4: 2837
A5: 12 | B5: 2922 | C5: 1591 | D5: 1331 | E5: 2967 | F5: 1638 | G5: 1329 | H5: 3148 | I5: 1710 | J5: 1438 | K5: 3755 | L5: 2127 | M5: 1628 | N5: 3762 | O5: 2039 | P5: 1723 | Q5: 3673 | R5: 2017 | S5: 1656 | T5: 3554 | U5: 1930 | V5: 1624
A6: 01 | B6: 2609 | C6: 1241 | D6: 1368 | E6: 2800 | F6: 1335 | G6: 1465 | H6: 2852 | I6: 1358 | J6: 1494 | K6: 3136 | L6: 1572 | M6: 1564 | N6: 3224 | O6: 1592 | P6: 1632 | Q6: 3384 | R6: 1632 | S6: 1752 | T6: 3216 | U6: 1578 | V6: 1638
A7: 07 | B7: 2078 | C7: 1140 | D7: 938 | E7: 2006 | F7: 1073 | G7: 933 | H7: 2105 | I7: 1133 | J7: 972 | K7: 2422 | L7: 1323 | M7: 1099 | N7: 2615 | O7: 1469 | P7: 1146 | Q7: 2655 | R7: 1438 | S7: 1217 | T7: 2730 | U7: 1462 | V7: 1268
A8: 18 | B8: 2000 | C8: 952 | D8: 1048 | E8: 2250 | F8: 1114 | G8: 1136 | H8: 2192 | I8: 1093 | J8: 1099 | K8: 2507 | L8: 1307 | M8: 1200 | N8: 2526 | O8: 1292 | P8: 1234 | Q8: 2413 | R8: 1219 | S8: 1194 | T8: 2448 | U8: 1193 | V8: 1255
A9: 06 | B9: 1814 | C9: 901 | D9: 913 | E9: 1764 | F9: 856 | G9: 908 | H9: 1775 | I9: 886 | J9: 889 | K9: 2145 | L9: 1131 | M9: 1014 | N9: 2049 | O9: 1068 | P9: 981 | Q9: 1946 | R9: 934 | S9: 1012 | T9: 1952 | U9: 977 | V9: 975
A10: 10 | B10: 1589 | C10: 772 | D10: 817 | E10: 1634 | F10: 842 | G10: 792 | H10: 1724 | I10: 851 | J10: 873 | K10: 1854 | L10: 934 | M10: 920 | N10: 1905 | O10: 973 | P10: 932 | Q10: 2038 | R10: 1014 | S10: 1024 | T10: 1938 | U10: 943 | V10: 995
A11: 11 | B11: 1367 | C11: 692 | D11: 675 | E11: 1387 | F11: 715 | G11: 672 | H11: 1431 | I11: 729 | J11: 702 | K11: 1586 | L11: 821 | M11: 765 | N11: 2183 | O11: 1128 | P11: 1055 | Q11: 2148 | R11: 1121 | S11: 1027 | T11: 2179 | U11: 1138 | V11: 1041
A12: 23 | B12: 1348 | C12: 700 | D12: 648 | E12: 1385 | F12: 734 | G12: 651 | H12: 1514 | I12: 835 | J12: 679 | K12: 1722 | L12: 946 | M12: 776 | N12: 1758 | O12: 982 | P12: 776 | Q12: 1762 | R12: 908 | S12: 854 | T12: 1746 | U12: 909 | V12: 837
A13: 05 | B13: 1182 | C13: 615 | D13: 567 | E13: 1418 | F13: 725 | G13: 693 | H13: 1490 | I13: 755 | J13: 735 | K13: 1680 | L13: 874 | M13: 806 | N13: 1865 | O13: 927 | P13: 938 | Q13: 1764 | R13: 881 | S13: 883 | T13: 1666 | U13: 847 | V13: 819
... A26: 20 | B26: 27 | C26: 16 | D26: 11 | E26: 41 | F26: 16 | G26: 25 | H26: 39 | I26: 22 | J26: 17 | K26: 32 | L26: 23 | M26: 9 | N26: 42 | O26: 28 | P26: 14 | Q26: 53 | R26: 29 | S26: 24 | T26: 49 | U26: 30 | V26: 19
A27: 90 | B27: 1 | C27: 1

Sheet TDPRVINCIAS
A1: prov_res | B1: Columna1 | C1: 2017 | D1: 2018 | E1: 2019 | F1: 2020 | G1: 2021 | H1: 2022 | I1: 2023 | J1: suma | K1: Columna3 | L1: Columna2 | M1: Hombres_2017 | N1: Hombres_2018 | O1: Hombres_2019 | P1: Hombres_2020 | Q1: Hombres_2021 | R1: Hombres_2022 | S1: Hombres_2023 | T1: Mujeres_2017 | U1: Mujeres_2018 | V1: Mujeres_2019 | W1: Mujeres_2020 | X1: Mujeres_2021 | Y1: Mujeres_2022 | Z1: Mujeres_2023 | AA1: VAR_AÑO1 | AB1: VAR_AÑO2 | AC1: VAR_AÑO3 | AD1: VAR_AÑO4 | AE1: VAR_AÑO5 | AF1: VAR_AÑO6 | AG1: PROMEDIO | AH1: MEDIA | AI1: VARAB_AÑO1 | AJ1: VARAB_AÑO2 | AK1: VARAB_AÑO3 | AL1: VARAB_AÑO4 | AM1: VARAB_AÑO5 | AN1: VARAB_AÑO6 | AO1: PROMEDIO2 | AP1: MEDIA2 | AQ1: VARH_AÑO1 | AR1: VARH_AÑO2 | AS1: VARH_AÑO3 | AT1: VARH_AÑO4 | AU1: VARH_AÑO5 | AV1: VARH_AÑO6 | AW1: PROMEDIO3 | AX1: MEDIA3 | AY1: VARAH_AÑO1 | AZ1: VARAH_AÑO2 | BA1: VARAH_AÑO3 | BB1: VARAH_AÑO4 | BC1: VARAH_AÑO5 | BD1: VARAH_AÑO6 | BE1: PROMEDIO4 | BF1: MEDIA4 | BG1: VARM_AÑO1 | BH1: VARM_AÑO2 | BI1: VARM_AÑO3 | BJ1: VARM_AÑO4 | BK1: VARM_AÑO5 | BL1: VARM_AÑO6 | BM1: PROMEDIO5 | BN1: MEDIANA | BO1: VARAM_AÑO1 | BP1: VARAM_AÑO2 | BQ1: VARAM_AÑO3 | BR1: VARAM_AÑO4 | BS1: VARAM_AÑO5 | BT1: VARAM_AÑO6 | BU1: PROMEDIO6 | BV1: MEDIA5
A2: 9 | B2: =_xlfn.XLOOKUP(Tabla10[[#This Row],[prov_res]],Hoja1!$A$34:$A$60,Hoja1!$B$34:$B$60,"",0) -> Guayas | C2: 15503 | D2: 15014 | E2: 15912 | F2: 27460 | G2: 18550 | H2: 18872 | I2: 17738 | J2: =+SUM(Tabla10[[#This Row],[2017]:[2023]]) -> 129049 | K2: =+AVERAGE(Tabla10[[#This Row],[2017]:[suma]]) -> 32262.25 | L2: =+MEDIAN(Tabla10[[#This Row],[2017]:[suma]]) -> 18144 | M2: 8132 | N2: 7777 | O2: 8305 | P2: 15682 | Q2: 9750 | R2: 9834 | S2: 9256 | T2: 7371 | U2: 7237 | V2: 7607 | W2: 11778 | X2: 8800 | Y2: 9038 | Z2: 8482 | AA2: =+(D2-C2)/C2 -> -0.031542282 | AB2: =+(E2-D2)/D2 -> 0.059810843 | AC2: =+(F2-E2)/E2 -> 0.72574158 | AD2: =+(G2-F2)/F2 -> -0.32447196 | AE2: =+(H2-G2)/G2 -> 0.017358491 | AF2: =+(I2-H2)/H2 -> -0.060089021 | AG2: =+AVERAGE(AA2:AF2) -> 0.064467942 | AH2: =MEDIAN(AA2:AF2) -> -0.0070918958 | AI2: =D2-C2 -> -489 | AJ2: =E2-D2 -> 898 | AK2: =F2-E2 -> 11548 | AL2: =G2-F2 -> -8910 | AM2: =H2-G2 -> 322 | AN2: =I2-H2 -> -1134 | AO2: =+AVERAGE(AI2:AN2) -> 372.5 | AP2: =+MEDIAN(AI2:AN2) -> -83.5 | AQ2: =+(N2-M2)/M2 -> -0.043654697 | AR2: =+(O2-N2)/N2 -> 0.067892504 | AS2: =+(P2-O2)/O2 -> 0.88826008 | AT2: =+(Q2-P2)/P2 -> -0.37826808 | AU2: =+(R2-Q2)/Q2 -> 0.0086153846 | AV2: =+(S2-R2)/R2 -> -0.058775676 | AW2: =+AVERAGE(AQ2:AV2) -> 0.080678253 | AX2: =+MEDIAN(AQ2:AV2) -> -0.017519656 | AY2: =N2-M2 -> -355 | AZ2: =O2-N2 -> 528 | BA2: =P2-O2 -> 7377 | BB2: =Q2-P2 -> -5932 | BC2: =R2-Q2 -> 84 | BD2: =S2-R2 -> -578 | BE2: =+AVERAGE(AY2:BD2) -> 187.33333 | BF2: =MEDIAN(AY2:BD2) -> -135.5 | BG2: =+(U2-T2)/T2 -> -0.018179352 | BH2: =+(V2-U2)/U2 -> 0.051126157 | BI2: =+(W2-V2)/V2 -> 0.54831077 | BJ2: =+(X2-W2)/W2 -> -0.25284429 | BK2: =+(Y2-X2)/X2 -> 0.027045455 | BL2: =+(Z2-Y2)/Y2 -> -0.061518035 | BM2: =+AVERAGE(BG2:BL2) -> 0.048990118 | BN2: =MEDIAN(BG2:BL2) -> 0.0044330515 | BO2: =+U2-T2 -> -134 | BP2: =+V2-U2 -> 370 | BQ2: =+W2-V2 -> 4171 | BR2: =+X2-W2 -> -2978 | BS2: =+Y2-X2 -> 238 | BT2: =+Z2-Y2 -> -556 | BU2: =+AVERAGE(BO2:BT2) -> 185.16667 | BV2: =MEDIAN(BO2:BT2) -> 52
